Workbook

Sheet Dashboard-Jan
A1: DashBoard | C1: Income Sources | D1: Count Price | E1: 46023 | F1: =E1+1 -> 46024 | G1: =F1+1 -> 46025 | H1: =G1+1 -> 46026 | I1: =H1+1 -> 46027 | J1: =I1+1 -> 46028 | K1: =J1+1 -> 46029 | L1: =K1+1 -> 46030 | M1: =L1+1 -> 46031 | ... AI1: =AH1+1 -> 46053 | AJ1: TOTAL
A2: Discretionary Cap | B2: 15000 | C2: Task-1 | D2: 50 | E2: ='1'!$V2 -> 0 | F2: ='2'!$V2 -> 0 | G2: ='3'!$V2 -> 0 | H2: ='4'!$V2 -> 0 | I2: ='5'!$V2 -> 0 | J2: ='6'!$V2 -> 0 | K2: ='7'!$V2 -> 0 | L2: ='8'!$V2 -> 0 | M2: ='9'!$V2 -> 0 | N2: ='10'!$V2 -> 0 | O2: ='11'!$V2 -> 0 | P2: ='12'!$V2 -> 0 | Q2: ='13'!$V2 -> 0 | R2: ='14'!$V2 -> 0 | S2: ='15'!$V2 -> 0 | T2: ='16'!$V2 -> 0 | U2: ='17'!$V2 -> 0 | V2: ='18'!$V2 -> 0 | W2: ='19'!$V2 -> 0 | X2: ='20'!$V2 -> 0 | Y2: ='21'!$V2 -> 0 | Z2: ='22'!$V2 -> 0 | AA2: ='23'!$V2 -> 0 | AB2: ='24'!$V2 -> 0 | AC2: ='25'!$V2 -> 0 | AD2: ='26'!$V2 -> 0 | AE2: ='27'!$V2 -> 0 | AF2: ='28'!$V2 -> 0 | AG2: ='29'!$V2 -> 0 | AH2: ='30'!$V2 -> 0 | AI2: ='31'!$V2 -> 0 | AJ2: =SUM(E2:AI2) -> 0
A3: Discipline Debit | B3: 750 | C3: Task-2 | D3: 25 | E3: ='1'!$V3 -> 0 | F3: ='2'!$V3 -> 0 | G3: ='3'!$V3 -> 0 | H3: ='4'!$V3 -> 0 | I3: ='5'!$V3 -> 0 | J3: ='6'!$V3 -> 0 | K3: ='7'!$V3 -> 0 | L3: ='8'!$V3 -> 0 | M3: ='9'!$V3 -> 0 | N3: ='10'!$V3 -> 0 | O3: ='11'!$V3 -> 0 | P3: ='12'!$V3 -> 0 | Q3: ='13'!$V3 -> 0 | R3: ='14'!$V3 -> 0 | S3: ='15'!$V3 -> 0 | T3: ='16'!$V3 -> 0 | U3: ='17'!$V3 -> 0 | V3: ='18'!$V3 -> 0 | W3: ='19'!$V3 -> 0 | X3: ='20'!$V3 -> 0 | Y3: ='21'!$V3 -> 0 | Z3: ='22'!$V3 -> 0 | AA3: ='23'!$V3 -> 0 | AB3: ='24'!$V3 -> 0 | AC3: ='25'!$V3 -> 0 | AD3: ='26'!$V3 -> 0 | AE3: ='27'!$V3 -> 0 | AF3: ='28'!$V3 -> 0 | AG3: ='29'!$V3 -> 0 | AH3: ='30'!$V3 -> 0 | AI3: ='31'!$V3 -> 0 | AJ3: =SUM(E3:AI3) -> 0
A4: Previous Month Balance | B4: 0 | C4: Task-3 | D4: 125 | E4: ='1'!$V4 -> 0 | F4: ='2'!$V4 -> 0 | G4: ='3'!$V4 -> 0 | H4: ='4'!$V4 -> 0 | I4: ='5'!$V4 -> 0 | J4: ='6'!$V4 -> 0 | K4: ='7'!$V4 -> 0 | L4: ='8'!$V4 -> 0 | M4: ='9'!$V4 -> 0 | N4: ='10'!$V4 -> 0 | O4: ='11'!$V4 -> 0 | P4: ='12'!$V4 -> 0 | Q4: ='13'!$V4 -> 0 | R4: ='14'!$V4 -> 0 | S4: ='15'!$V4 -> 0 | T4: ='16'!$V4 -> 0 | U4: ='17'!$V4 -> 0 | V4: ='18'!$V4 -> 0 | W4: ='19'!$V4 -> 0 | X4: ='20'!$V4 -> 0 | Y4: ='21'!$V4 -> 0 | Z4: ='22'!$V4 -> 0 | AA4: ='23'!$V4 -> 0 | AB4: ='24'!$V4 -> 0 | AC4: ='25'!$V4 -> 0 | AD4: ='26'!$V4 -> 0 | AE4: ='27'!$V4 -> 0 | AF4: ='28'!$V4 -> 0 | AG4: ='29'!$V4 -> 0 | AH4: ='30'!$V4 -> 0 | AI4: ='31'!$V4 -> 0 | AJ4: =SUM(E4:AI4) -> 0
A5: Total Income | B5: =SUM(AJ2:AJ8) -> 0 | C5: Task-4 | D5: 35 | E5: ='1'!$V5 -> 0 | F5: ='2'!$V5 -> 0 | G5: ='3'!$V5 -> 0 | H5: ='4'!$V5 -> 0 | I5: ='5'!$V5 -> 0 | J5: ='6'!$V5 -> 0 | K5: ='7'!$V5 -> 0 | L5: ='8'!$V5 -> 0 | M5: ='9'!$V5 -> 0 | N5: ='10'!$V5 -> 0 | O5: ='11'!$V5 -> 0 | P5: ='12'!$V5 -> 0 | Q5: ='13'!$V5 -> 0 | R5: ='14'!$V5 -> 0 | S5: ='15'!$V5 -> 0 | T5: ='16'!$V5 -> 0 | U5: ='17'!$V5 -> 0 | V5: ='18'!$V5 -> 0 | W5: ='19'!$V5 -> 0 | X5: ='20'!$V5 -> 0 | Y5: ='21'!$V5 -> 0 | Z5: ='22'!$V5 -> 0 | AA5: ='23'!$V5 -> 0 | AB5: ='24'!$V5 -> 0 | AC5: ='25'!$V5 -> 0 | AD5: ='26'!$V5 -> 0 | AE5: ='27'!$V5 -> 0 | AF5: ='28'!$V5 -> 0 | AG5: ='29'!$V5 -> 0 | AH5: ='30'!$V5 -> 0 | AI5: ='31'!$V5 -> 0 | AJ5: =SUM(E5:AI5) -> 0
A6: Accrued Bonuses | B6: =SUM(AJ9:AJ11) -> 0 | C6: Task-5 | D6: 100 | E6: ='1'!$V6 -> 0 | F6: ='2'!$V6 -> 0 | G6: ='3'!$V6 -> 0 | H6: ='4'!$V6 -> 0 | I6: ='5'!$V6 -> 0 | J6: ='6'!$V6 -> 0 | K6: ='7'!$V6 -> 0 | L6: ='8'!$V6 -> 0 | M6: ='9'!$V6 -> 0 | N6: ='10'!$V6 -> 0 | O6: ='11'!$V6 -> 0 | P6: ='12'!$V6 -> 0 | Q6: ='13'!$V6 -> 0 | R6: ='14'!$V6 -> 0 | S6: ='15'!$V6 -> 0 | T6: ='16'!$V6 -> 0 | U6: ='17'!$V6 -> 0 | V6: ='18'!$V6 -> 0 | W6: ='19'!$V6 -> 0 | X6: ='20'!$V6 -> 0 | Y6: ='21'!$V6 -> 0 | Z6: ='22'!$V6 -> 0 | AA6: ='23'!$V6 -> 0 | AB6: ='24'!$V6 -> 0 | AC6: ='25'!$V6 -> 0 | AD6: ='26'!$V6 -> 0 | AE6: ='27'!$V6 -> 0 | AF6: ='28'!$V6 -> 0 | AG6: ='29'!$V6 -> 0 | AH6: ='30'!$V6 -> 0 | AI6: ='31'!$V6 -> 0 | AJ6: =SUM(E6:AI6) -> 0
A7: Gross Revenue | B7: =IF(AJ12 > B2,B2,AJ12+B4) -> -13500 | C7: Task-6 | D7: 150 | E7: ='1'!$V7 -> 0 | F7: ='2'!$V7 -> 0 | G7: ='3'!$V7 -> 0 | H7: ='4'!$V7 -> 0 | I7: ='5'!$V7 -> 0 | J7: ='6'!$V7 -> 0 | K7: ='7'!$V7 -> 0 | L7: ='8'!$V7 -> 0 | M7: ='9'!$V7 -> 0 | N7: ='10'!$V7 -> 0 | O7: ='11'!$V7 -> 0 | P7: ='12'!$V7 -> 0 | Q7: ='13'!$V7 -> 0 | R7: ='14'!$V7 -> 0 | S7: ='15'!$V7 -> 0 | T7: ='16'!$V7 -> 0 | U7: ='17'!$V7 -> 0 | V7: ='18'!$V7 -> 0 | W7: ='19'!$V7 -> 0 | X7: ='20'!$V7 -> 0 | Y7: ='21'!$V7 -> 0 | Z7: ='22'!$V7 -> 0 | AA7: ='23'!$V7 -> 0 | AB7: ='24'!$V7 -> 0 | AC7: ='25'!$V7 -> 0 | AD7: ='26'!$V7 -> 0 | AE7: ='27'!$V7 -> 0 | AF7: ='28'!$V7 -> 0 | AG7: ='29'!$V7 -> 0 | AH7: ='30'!$V7 -> 0 | AI7: ='31'!$V7 -> 0 | AJ7: =SUM(E7:AI7) -> 0
A8: Redeemed Rewards | B8: =AJ17 -> 0 | C8: Task-7 | D8: 150 | E8: ='1'!$V8 -> 0 | F8: ='2'!$V8 -> 0 | G8: ='3'!$V8 -> 0 | H8: ='4'!$V8 -> 0 | I8: ='5'!$V8 -> 0 | J8: ='6'!$V8 -> 0 | K8: ='7'!$V8 -> 0 | L8: ='8'!$V8 -> 0 | M8: ='9'!$V8 -> 0 | N8: ='10'!$V8 -> 0 | O8: ='11'!$V8 -> 0 | P8: ='12'!$V8 -> 0 | Q8: ='13'!$V8 -> 0 | R8: ='14'!$V8 -> 0 | S8: ='15'!$V8 -> 0 | T8: ='16'!$V8 -> 0 | U8: ='17'!$V8 -> 0 | V8: ='18'!$V8 -> 0 | W8: ='19'!$V8 -> 0 | X8: ='20'!$V8 -> 0 | Y8: ='21'!$V8 -> 0 | Z8: ='22'!$V8 -> 0 | AA8: ='23'!$V8 -> 0 | AB8: ='24'!$V8 -> 0 | AC8: ='25'!$V8 -> 0 | AD8: ='26'!$V8 -> 0 | AE8: ='27'!$V8 -> 0 | AF8: ='28'!$V8 -> 0 | AG8: ='29'!$V8 -> 0 | AH8: ='30'!$V8 -> 0 | AI8: ='31'!$V8 -> 0 | AJ8: =SUM(E8:AI8) -> 0
A9: NET MOTIVATION BALANCE | B9: =B7-B8 -> -13500 | C9: Combo Bonus | D9: 25 | E9: =Max('1'!$B$9:$U$9)*$D$9 -> 0 | F9: =Max('2'!$B$9:$U$9)*$D$9 -> 0 | G9: =Max('3'!$B$9:$U$9)*$D$9 -> 0 | H9: =Max('4'!$B$9:$U$9)*$D$9 -> 0 | I9: =Max('5'!$B$9:$U$9)*$D$9 -> 0 | J9: =Max('6'!$B$9:$U$9)*$D$9 -> 0 | K9: =Max('7'!$B$9:$U$9)*$D$9 -> 0 | L9: =Max('8'!$B$9:$U$9)*$D$9 -> 0 | M9: =Max('9'!$B$9:$U$9)*$D$9 -> 0 | N9: =Max('10'!$B$9:$U$9)*$D$9 -> 0 | O9: =Max('11'!$B$9:$U$9)*$D$9 -> 0 | P9: =Max('12'!$B$9:$U$9)*$D$9 -> 0 | Q9: =Max('13'!$B$9:$U$9)*$D$9 -> 0 | R9: =Max('14'!$B$9:$U$9)*$D$9 -> 0 | S9: =Max('15'!$B$9:$U$9)*$D$9 -> 0 | T9: =Max('16'!$B$9:$U$9)*$D$9 -> 0 | U9: =Max('17'!$B$9:$U$9)*$D$9 -> 0 | V9: =Max('18'!$B$9:$U$9)*$D$9 -> 0 | W9: =Max('19'!$B$9:$U$9)*$D$9 -> 0 | X9: =Max('20'!$B$9:$U$9)*$D$9 -> 0 | Y9: =Max('21'!$B$9:$U$9)*$D$9 -> 0 | Z9: =Max('22'!$B$9:$U$9)*$D$9 -> 0 | AA9: =Max('23'!$B$9:$U$9)*$D$9 -> 0 | AB9: =Max('24'!$B$9:$U$9)*$D$9 -> 0 | AC9: =Max('25'!$B$9:$U$9)*$D$9 -> 0 | AD9: =Max('26'!$B$9:$U$9)*$D$9 -> 0 | AE9: =Max('27'!$B$9:$U$9)*$D$9 -> 0 | AF9: =Max('28'!$B$9:$U$9)*$D$9 -> 0 | AG9: =Max('29'!$B$9:$U$9)*$D$9 -> 0 | AH9: =Max('30'!$B$9:$U$9)*$D$9 -> 0 | AI9: =Max('31'!$B$9:$U$9)*$D$9 -> 0 | AJ9: =SUM(E9:AI9) -> 0
C10: Streak Multiplier | D10: 0.1 | E10: ='1'!$W$9*100*$D$10 -> 0 | F10: ='2'!$W$9*100*$D$10 -> 0 | G10: ='3'!$W$9*100*$D$10 -> 0 | H10: ='4'!$W$9*100*$D$10 -> 0 | I10: ='5'!$W$9*100*$D$10 -> 0 | J10: ='6'!$W$9*100*$D$10 -> 0 | K10: ='7'!$W$9*100*$D$10 -> 0 | L10: ='8'!$W$9*100*$D$10 -> 0 | M10: ='9'!$W$9*100*$D$10 -> 0 | N10: ='10'!$W$9*100*$D$10 -> 0 | O10: ='11'!$W$9*100*$D$10 -> 0 | P10: ='12'!$W$9*100*$D$10 -> 0 | Q10: ='13'!$W$9*100*$D$10 -> 0 | R10: ='14'!$W$9*100*$D$10 -> 0 | S10: ='15'!$W$9*100*$D$10 -> 0 | T10: ='16'!$W$9*100*$D$10 -> 0 | U10: ='17'!$W$9*100*$D$10 -> 0 | V10: ='18'!$W$9*100*$D$10 -> 0 | W10: ='19'!$W$9*100*$D$10 -> 0 | X10: ='20'!$W$9*100*$D$10 -> 0 | Y10: ='21'!$W$9*100*$D$10 -> 0 | Z10: ='22'!$W$9*100*$D$10 -> 0 | AA10: ='23'!$W$9*100*$D$10 -> 0 | AB10: ='24'!$W$9*100*$D$10 -> 0 | AC10: ='25'!$W$9*100*$D$10 -> 0 | AD10: ='26'!$W$9*100*$D$10 -> 0 | AE10: ='27'!$W$9*100*$D$10 -> 0 | AF10: ='28'!$W$9*100*$D$10 -> 0 | AG10: ='29'!$W$9*100*$D$10 -> 0 | AH10: ='30'!$W$9*100*$D$10 -> 0 | AI10: ='31'!$W$9*100*$D$10 -> 0 | AJ10: =SUM(E10:AI10) -> 0
C11: Recurring Bonus | D11: 10 | E11: =Sum('1'!$B$9:$U$9)*$D$11 -> 0 | F11: =Sum('2'!$B$9:$U$9)*$D$11 -> 0 | G11: =Sum('3'!$B$9:$U$9)*$D$11 -> 0 | H11: =Sum('1'!$B$9:$U$9)*$D$11 -> 0 | I11: =Sum('5'!$B$9:$U$9)*$D$11 -> 0 | J11: =Sum('6'!$B$9:$U$9)*$D$11 -> 0 | K11: =Sum('7'!$B$9:$U$9)*$D$11 -> 0 | L11: =Sum('8'!$B$9:$U$9)*$D$11 -> 0 | M11: =Sum('9'!$B$9:$U$9)*$D$11 -> 0 | N11: =Sum('10'!$B$9:$U$9)*$D$11 -> 0 | O11: =Sum('11'!$B$9:$U$9)*$D$11 -> 0 | P11: =Sum('12'!$B$9:$U$9)*$D$11 -> 0 | Q11: =Sum('13'!$B$9:$U$9)*$D$11 -> 0 | R11: =Sum('14'!$B$9:$U$9)*$D$11 -> 0 | S11: =Sum('15'!$B$9:$U$9)*$D$11 -> 0 | T11: =Sum('16'!$B$9:$U$9)*$D$11 -> 0 | U11: =Sum('17'!$B$9:$U$9)*$D$11 -> 0 | V11: =Sum('18'!$B$9:$U$9)*$D$11 -> 0 | W11: =Sum('19'!$B$9:$U$9)*$D$11 -> 0 | X11: =Sum('20'!$B$9:$U$9)*$D$11 -> 0 | Y11: =Sum('21'!$B$9:$U$9)*$D$11 -> 0 | Z11: =Sum('22'!$B$9:$U$9)*$D$11 -> 0 | AA11: =Sum('23'!$B$9:$U$9)*$D$11 -> 0 | AB11: =Sum('24'!$B$9:$U$9)*$D$11 -> 0 | AC11: =Sum('25'!$B$9:$U$9)*$D$11 -> 0 | AD11: =Sum('26'!$B$9:$U$9)*$D$11 -> 0 | AE11: =Sum('27'!$B$9:$U$9)*$D$11 -> 0 | AF11: =Sum('28'!$B$9:$U$9)*$D$11 -> 0 | AG11: =Sum('29'!$B$9:$U$9)*$D$11 -> 0 | AH11: =Sum('30'!$B$9:$U$9)*$D$11 -> 0 | AI11: =Sum('31'!$B$9:$U$9)*$D$11 -> 0 | AJ11: =SUM(E11:AI11) -> 0
C12: TOTAL | E12: =IF(AND(E1 < TODAY(), Sum(E2:E8) = 0), -B3, Sum(E2:E11)) -> -750 | F12: =IF(AND(F1 < TODAY(), Sum(F2:F8) = 0), -$B$3, Sum(F2:F11)) -> -750 | G12: =IF(AND(G1 < TODAY(), Sum(G2:G8) = 0), -$B$3, Sum(G2:G11)) -> -750 | H12: =IF(AND(H1 < TODAY(), Sum(H2:H8) = 0), -$B$3, Sum(H2:H11)) -> -750 | I12: =IF(AND(I1 < TODAY(), Sum(I2:I8) = 0), -$B$3, Sum(I2:I11)) -> -750 | J12: =IF(AND(J1 < TODAY(), Sum(J2:J8) = 0), -$B$3, Sum(J2:J11)) -> -750 | K12: =IF(AND(K1 < TODAY(), Sum(K2:K8) = 0), -$B$3, Sum(K2:K11)) -> -750 | L12: =IF(AND(L1 < TODAY(), Sum(L2:L8) = 0), -$B$3, Sum(L2:L11)) -> -750 | M12: =IF(AND(M1 < TODAY(), Sum(M2:M8) = 0), -$B$3, Sum(M2:M11)) -> -750 | ... AI12: =IF(AND(AI1 < TODAY(), Sum(AI2:AI8) = 0), -$B$3, Sum(AI2:AI11)) -> 0 | AJ12: =SUM(E12:AI12) -> -13500
C13: Target Rewards | E13: 46023 | F13: =E13+1 -> 46024 | G13: =F13+1 -> 46025 | H13: =G13+1 -> 46026 | I13: =H13+1 -> 46027 | J13: =I13+1 -> 46028 | K13: =J13+1 -> 46029 | L13: =K13+1 -> 46030 | M13: =L13+1 -> 46031 | ... AI13: =AH13+1 -> 46053 | AJ13: TOTAL
C14: Reward-1 | D14: 1 | E14: ='1'!$V11 -> 0 | F14: ='2'!$V11 -> 0 | G14: ='3'!$V11 -> 0 | H14: ='4'!$V11 -> 0 | I14: ='5'!$V11 -> 0 | J14: ='6'!$V11 -> 0 | K14: ='7'!$V11 -> 0 | L14: ='8'!$V11 -> 0 | M14: ='9'!$V11 -> 0 | N14: ='10'!$V11 -> 0 | O14: ='11'!$V11 -> 0 | P14: ='12'!$V11 -> 0 | Q14: ='13'!$V11 -> 0 | R14: ='14'!$V11 -> 0 | S14: ='15'!$V11 -> 0 | T14: ='16'!$V11 -> 0 | U14: ='17'!$V11 -> 0 | V14: ='18'!$V11 -> 0 | W14: ='19'!$V11 -> 0 | X14: ='20'!$V11 -> 0 | Y14: ='21'!$V11 -> 0 | Z14: ='22'!$V11 -> 0 | AA14: ='23'!$V11 -> 0 | AB14: ='24'!$V11 -> 0 | AC14: ='25'!$V11 -> 0 | AD14: ='26'!$V11 -> 0 | AE14: ='27'!$V11 -> 0 | AF14: ='28'!$V11 -> 0 | AG14: ='29'!$V11 -> 0 | AH14: ='30'!$V11 -> 0 | AI14: ='31'!$V11 -> 0 | AJ14: =SUM(E14:AI14) -> 0
C15: Reward-2 | D15: 1 | E15: ='1'!$V12 -> 0 | F15: ='2'!$V12 -> 0 | G15: ='3'!$V12 -> 0 | H15: ='4'!$V12 -> 0 | I15: ='5'!$V12 -> 0 | J15: ='6'!$V12 -> 0 | K15: ='7'!$V12 -> 0 | L15: ='8'!$V12 -> 0 | M15: ='9'!$V12 -> 0 | N15: ='10'!$V12 -> 0 | O15: ='11'!$V12 -> 0 | P15: ='12'!$V12 -> 0 | Q15: ='13'!$V12 -> 0 | R15: ='14'!$V12 -> 0 | S15: ='15'!$V12 -> 0 | T15: ='16'!$V12 -> 0 | U15: ='17'!$V12 -> 0 | V15: ='18'!$V12 -> 0 | W15: ='19'!$V12 -> 0 | X15: ='20'!$V12 -> 0 | Y15: ='21'!$V12 -> 0 | Z15: ='22'!$V12 -> 0 | AA15: ='23'!$V12 -> 0 | AB15: ='24'!$V12 -> 0 | AC15: ='25'!$V12 -> 0 | AD15: ='26'!$V12 -> 0 | AE15: ='27'!$V12 -> 0 | AF15: ='28'!$V12 -> 0 | AG15: ='29'!$V12 -> 0 | AH15: ='30'!$V12 -> 0 | AI15: ='31'!$V12 -> 0 | AJ15: =SUM(E15:AI15) -> 0
C16: Reward-3 | D16: 1 | E16: ='1'!$V13 -> 0 | F16: ='2'!$V13 -> 0 | G16: ='3'!$V13 -> 0 | H16: ='4'!$V13 -> 0 | I16: ='5'!$V13 -> 0 | J16: ='6'!$V13 -> 0 | K16: ='7'!$V13 -> 0 | L16: ='8'!$V13 -> 0 | M16: ='9'!$V13 -> 0 | N16: ='10'!$V13 -> 0 | O16: ='11'!$V13 -> 0 | P16: ='12'!$V13 -> 0 | Q16: ='13'!$V13 -> 0 | R16: ='14'!$V13 -> 0 | S16: ='15'!$V13 -> 0 | T16: ='16'!$V13 -> 0 | U16: ='17'!$V13 -> 0 | V16: ='18'!$V13 -> 0 | W16: ='19'!$V13 -> 0 | X16: ='20'!$V13 -> 0 | Y16: ='21'!$V13 -> 0 | Z16: ='22'!$V13 -> 0 | AA16: ='23'!$V13 -> 0 | AB16: ='24'!$V13 -> 0 | AC16: ='25'!$V13 -> 0 | AD16: ='26'!$V13 -> 0 | AE16: ='27'!$V13 -> 0 | AF16: ='28'!$V13 -> 0 | AG16: ='29'!$V13 -> 0 | AH16: ='30'!$V13 -> 0 | AI16: ='31'!$V13 -> 0 | AJ16: =SUM(E16:AI16) -> 0
C17: TOTAL | E17: =SUM(E14:E16) -> 0 | F17: =SUM(F14:F16) -> 0 | G17: =SUM(G14:G16) -> 0 | H17: =SUM(H14:H16) -> 0 | I17: =SUM(I14:I16) -> 0 | J17: =SUM(J14:J16) -> 0 | K17: =SUM(K14:K16) -> 0 | L17: =SUM(L14:L16) -> 0 | ... AJ17: =SUM(AJ14:AJ16) -> 0

Sheet 1
A1: Task Name | B1: 1 | C1: 2 | D1: 3 | E1: 4 | F1: 5 | G1: 6 | H1: 7 | I1: 8 | J1: 9 | K1: 10 | L1: 11 | M1: 12 | N1: 13 | O1: 14 | P1: 15 | Q1: 16 | R1: 17 | S1: 18 | T1: 19 | U1: 20 | V1: Total | W1: Streak
A2: ='Dashboard-Jan'!$C2 -> Task-1 | V2: =('Dashboard-Jan'!D2)*(SUM(B2:U2)) -> 0 | W2: 0
A3: ='Dashboard-Jan'!$C3 -> Task-2 | V3: =('Dashboard-Jan'!D3)*(SUM(B3:U3)) -> 0 | W3: 0
A4: ='Dashboard-Jan'!$C4 -> Task-3 | V4: =('Dashboard-Jan'!D4)*(SUM(B4:U4)) -> 0 | W4: 0
A5: ='Dashboard-Jan'!$C5 -> Task-4 | V5: =('Dashboard-Jan'!D5)*(SUM(B5:U5)) -> 0 | W5: 0
A6: ='Dashboard-Jan'!$C6 -> Task-5 | V6: =('Dashboard-Jan'!D6)*(SUM(B6:U6)) -> 0 | W6: 0
A7: ='Dashboard-Jan'!$C7 -> Task-6 | V7: =('Dashboard-Jan'!D7)*(SUM(B7:U7)) -> 0 | W7: 0
A8: ='Dashboard-Jan'!$C8 -> Task-7 | V8: =('Dashboard-Jan'!D8)*(SUM(B8:U8)) -> 0 | W8: 0
A9: TOTAL | B9: =SUM(B2:B8) -> 0 | C9: =SUM(C2:C8) -> 0 | D9: =SUM(D2:D8) -> 0 | E9: =SUM(E2:E8) -> 0 | F9: =SUM(F2:F8) -> 0 | G9: =SUM(G2:G8) -> 0 | H9: =SUM(H2:H8) -> 0 | I9: =SUM(I2:I8) -> 0 | ... V9: =SUM(V2:V8) -> 0
A10: Expense Item | B10: 1 | C10: 2 | D10: 3 | E10: 4 | F10: 5 | G10: 6 | H10: 7 | I10: 8 | J10: 9 | K10: 10 | L10: 11 | M10: 12 | N10: 13 | O10: 14 | P10: 15 | Q10: 16 | R10: 17 | S10: 18 | T10: 19 | U10: 20 | V10: Total
A11: ='Dashboard-Jan'!$C14 -> Reward-1 | V11: =('Dashboard-Jan'!D14)*(SUM(B11:U11)) -> 0
A12: ='Dashboard-Jan'!$C15 -> Reward-2 | V12: =('Dashboard-Jan'!D15)*(SUM(B12:U12)) -> 0
A13: ='Dashboard-Jan'!$C16 -> Reward-3 | V13: =('Dashboard-Jan'!D16)*(SUM(B13:U13)) -> 0
A14: TOTAL | B14: =SUM(B11:B13) -> 0 | C14: =SUM(C11:C13) -> 0 | D14: =SUM(D11:D13) -> 0 | E14: =SUM(E11:E13) -> 0 | F14: =SUM(F11:F13) -> 0 | G14: =SUM(G11:G13) -> 0 | H14: =SUM(H11:H13) -> 0 | I14: =SUM(I11:I13) -> 0 | ... V14: =SUM(V11:V13) -> 0

Sheet 2
A1: 2 | B1: 1 | C1: 2 | D1: 3 | E1: 4 | F1: 5 | G1: 6 | H1: 7 | I1: 8 | J1: 9 | K1: 10 | L1: 11 | M1: 12 | N1: 13 | O1: 14 | P1: 15 | Q1: 16 | R1: 17 | S1: 18 | T1: 19 | U1: 20 | V1: Total | W1: Streak
A2: ='Dashboard-Jan'!$C2 -> Task-1 | V2: =(('Dashboard-Jan'!D2)*(SUM(B2:U2)))*((W2*'Dashboard-Jan'!$D$10)+1) -> 0 | W2: =IF('1'!V2 <> 0,('1'!W2)+1,0) -> 0
A3: ='Dashboard-Jan'!$C3 -> Task-2 | V3: =(('Dashboard-Jan'!D3)*(SUM(B3:U3)))*((W3*'Dashboard-Jan'!$D$10)+1) -> 0 | W3: =IF('1'!V3 <> 0,('1'!W3)+1,0) -> 0
A4: ='Dashboard-Jan'!$C4 -> Task-3 | V4: =(('Dashboard-Jan'!D4)*(SUM(B4:U4)))*((W4*'Dashboard-Jan'!$D$10)+1) -> 0 | W4: =IF('1'!V4 <> 0,('1'!W4)+1,0) -> 0
A5: ='Dashboard-Jan'!$C5 -> Task-4 | V5: =(('Dashboard-Jan'!D5)*(SUM(B5:U5)))*((W5*'Dashboard-Jan'!$D$10)+1) -> 0 | W5: =IF('1'!V5 <> 0,('1'!W5)+1,0) -> 0
A6: ='Dashboard-Jan'!$C6 -> Task-5 | V6: =(('Dashboard-Jan'!D6)*(SUM(B6:U6)))*((W6*'Dashboard-Jan'!$D$10)+1) -> 0 | W6: =IF('1'!V6 <> 0,('1'!W6)+1,0) -> 0
A7: ='Dashboard-Jan'!$C7 -> Task-6 | V7: =(('Dashboard-Jan'!D7)*(SUM(B7:U7)))*((W7*'Dashboard-Jan'!$D$10)+1) -> 0 | W7: =IF('1'!V7 <> 0,('1'!W7)+1,0) -> 0
A8: ='Dashboard-Jan'!$C8 -> Task-7 | V8: =(('Dashboard-Jan'!D8)*(SUM(B8:U8)))*((W8*'Dashboard-Jan'!$D$10)+1) -> 0 | W8: =IF('1'!V8 <> 0,('1'!W8)+1,0) -> 0
A9: TOTAL | B9: =SUM(B2:B8) -> 0 | C9: =SUM(C2:C8) -> 0 | D9: =SUM(D2:D8) -> 0 | E9: =SUM(E2:E8) -> 0 | F9: =SUM(F2:F8) -> 0 | G9: =SUM(G2:G8) -> 0 | H9: =SUM(H2:H8) -> 0 | I9: =SUM(I2:I8) -> 0 | ... V9: =SUM(V2:V8) -> 0
A10: Expense Item | B10: 1 | C10: 2 | D10: 3 | E10: 4 | F10: 5 | G10: 6 | H10: 7 | I10: 8 | J10: 9 | K10: 10 | L10: 11 | M10: 12 | N10: 13 | O10: 14 | P10: 15 | Q10: 16 | R10: 17 | S10: 18 | T10: 19 | U10: 20 | V10: Total
A11: ='Dashboard-Jan'!$C14 -> Reward-1 | V11: =('Dashboard-Jan'!D14)*(SUM(B11:U11)) -> 0
A12: ='Dashboard-Jan'!$C15 -> Reward-2 | V12: =('Dashboard-Jan'!D15)*(SUM(B12:U12)) -> 0
A13: ='Dashboard-Jan'!$C16 -> Reward-3 | V13: =('Dashboard-Jan'!D16)*(SUM(B13:U13)) -> 0
A14: TOTAL | B14: =SUM(B11:B13) -> 0 | C14: =SUM(C11:C13) -> 0 | D14: =SUM(D11:D13) -> 0 | E14: =SUM(E11:E13) -> 0 | F14: =SUM(F11:F13) -> 0 | G14: =SUM(G11:G13) -> 0 | H14: =SUM(H11:H13) -> 0 | I14: =SUM(I11:I13) -> 0 | ... V14: =SUM(V11:V13) -> 0

Sheet 3
A1: Task Name | B1: 1 | C1: 2 | D1: 3 | E1: 4 | F1: 5 | G1: 6 | H1: 7 | I1: 8 | J1: 9 | K1: 10 | L1: 11 | M1: 12 | N1: 13 | O1: 14 | P1: 15 | Q1: 16 | R1: 17 | S1: 18 | T1: 19 | U1: 20 | V1: Total | W1: Streak
A2: ='Dashboard-Jan'!$C2 -> Task-1 | V2: =(('Dashboard-Jan'!D2)*(SUM(B2:U2)))*((W2*'Dashboard-Jan'!$D$10)+1) -> 0 | W2: =IF('2'!V2 <> 0,('2'!W2)+1,0) -> 0
A3: ='Dashboard-Jan'!$C3 -> Task-2 | V3: =(('Dashboard-Jan'!D3)*(SUM(B3:U3)))*((W3*'Dashboard-Jan'!$D$10)+1) -> 0 | W3: =IF('2'!V3 <> 0,('2'!W3)+1,0) -> 0
A4: ='Dashboard-Jan'!$C4 -> Task-3 | V4: =(('Dashboard-Jan'!D4)*(SUM(B4:U4)))*((W4*'Dashboard-Jan'!$D$10)+1) -> 0 | W4: =IF('2'!V4 <> 0,('2'!W4)+1,0) -> 0
A5: ='Dashboard-Jan'!$C5 -> Task-4 | V5: =(('Dashboard-Jan'!D5)*(SUM(B5:U5)))*((W5*'Dashboard-Jan'!$D$10)+1) -> 0 | W5: =IF('2'!V5 <> 0,('2'!W5)+1,0) -> 0
A6: ='Dashboard-Jan'!$C6 -> Task-5 | V6: =(('Dashboard-Jan'!D6)*(SUM(B6:U6)))*((W6*'Dashboard-Jan'!$D$10)+1) -> 0 | W6: =IF('2'!V6 <> 0,('2'!W6)+1,0) -> 0
A7: ='Dashboard-Jan'!$C7 -> Task-6 | V7: =(('Dashboard-Jan'!D7)*(SUM(B7:U7)))*((W7*'Dashboard-Jan'!$D$10)+1) -> 0 | W7: =IF('2'!V7 <> 0,('2'!W7)+1,0) -> 0
A8: ='Dashboard-Jan'!$C8 -> Task-7 | V8: =(('Dashboard-Jan'!D8)*(SUM(B8:U8)))*((W8*'Dashboard-Jan'!$D$10)+1) -> 0 | W8: =IF('2'!V8 <> 0,('2'!W8)+1,0) -> 0
A9: TOTAL | B9: =SUM(B2:B8) -> 0 | C9: =SUM(C2:C8) -> 0 | D9: =SUM(D2:D8) -> 0 | E9: =SUM(E2:E8) -> 0 | F9: =SUM(F2:F8) -> 0 | G9: =SUM(G2:G8) -> 0 | H9: =SUM(H2:H8) -> 0 | I9: =SUM(I2:I8) -> 0 | ... V9: =SUM(V2:V8) -> 0
A10: Expense Item | B10: 1 | C10: 2 | D10: 3 | E10: 4 | F10: 5 | G10: 6 | H10: 7 | I10: 8 | J10: 9 | K10: 10 | L10: 11 | M10: 12 | N10: 13 | O10: 14 | P10: 15 | Q10: 16 | R10: 17 | S10: 18 | T10: 19 | U10: 20 | V10: Total
A11: ='Dashboard-Jan'!$C14 -> Reward-1 | V11: =('Dashboard-Jan'!D14)*(SUM(B11:U11)) -> 0
A12: ='Dashboard-Jan'!$C15 -> Reward-2 | V12: =('Dashboard-Jan'!D15)*(SUM(B12:U12)) -> 0
A13: ='Dashboard-Jan'!$C16 -> Reward-3 | V13: =('Dashboard-Jan'!D16)*(SUM(B13:U13)) -> 0
A14: TOTAL | B14: =SUM(B11:B13) -> 0 | C14: =SUM(C11:C13) -> 0 | D14: =SUM(D11:D13) -> 0 | E14: =SUM(E11:E13) -> 0 | F14: =SUM(F11:F13) -> 0 | G14: =SUM(G11:G13) -> 0 | H14: =SUM(H11:H13) -> 0 | I14: =SUM(I11:I13) -> 0 | ... V14: =SUM(V11:V13) -> 0

Sheet 4
A1: Task Name | B1: 1 | C1: 2 | D1: 3 | E1: 4 | F1: 5 | G1: 6 | H1: 7 | I1: 8 | J1: 9 | K1: 10 | L1: 11 | M1: 12 | N1: 13 | O1: 14 | P1: 15 | Q1: 16 | R1: 17 | S1: 18 | T1: 19 | U1: 20 | V1: Total | W1: Streak
A2: ='Dashboard-Jan'!$C2 -> Task-1 | V2: =(('Dashboard-Jan'!D2)*(SUM(B2:U2)))*((W2*'Dashboard-Jan'!$D$10)+1) -> 0 | W2: =IF('3'!V2 <> 0,('3'!W2)+1,0) -> 0
A3: ='Dashboard-Jan'!$C3 -> Task-2 | V3: =(('Dashboard-Jan'!D3)*(SUM(B3:U3)))*((W3*'Dashboard-Jan'!$D$10)+1) -> 0 | W3: =IF('3'!V3 <> 0,('3'!W3)+1,0) -> 0
A4: ='Dashboard-Jan'!$C4 -> Task-3 | V4: =(('Dashboard-Jan'!D4)*(SUM(B4:U4)))*((W4*'Dashboard-Jan'!$D$10)+1) -> 0 | W4: =IF('3'!V4 <> 0,('3'!W4)+1,0) -> 0
A5: ='Dashboard-Jan'!$C5 -> Task-4 | V5: =(('Dashboard-Jan'!D5)*(SUM(B5:U5)))*((W5*'Dashboard-Jan'!$D$10)+1) -> 0 | W5: =IF('3'!V5 <> 0,('3'!W5)+1,0) -> 0
A6: ='Dashboard-Jan'!$C6 -> Task-5 | V6: =(('Dashboard-Jan'!D6)*(SUM(B6:U6)))*((W6*'Dashboard-Jan'!$D$10)+1) -> 0 | W6: =IF('3'!V6 <> 0,('3'!W6)+1,0) -> 0
A7: ='Dashboard-Jan'!$C7 -> Task-6 | V7: =(('Dashboard-Jan'!D7)*(SUM(B7:U7)))*((W7*'Dashboard-Jan'!$D$10)+1) -> 0 | W7: =IF('3'!V7 <> 0,('3'!W7)+1,0) -> 0
A8: ='Dashboard-Jan'!$C8 -> Task-7 | V8: =(('Dashboard-Jan'!D8)*(SUM(B8:U8)))*((W8*'Dashboard-Jan'!$D$10)+1) -> 0 | W8: =IF('3'!V8 <> 0,('3'!W8)+1,0) -> 0
A9: TOTAL | B9: =SUM(B2:B8) -> 0 | C9: =SUM(C2:C8) -> 0 | D9: =SUM(D2:D8) -> 0 | E9: =SUM(E2:E8) -> 0 | F9: =SUM(F2:F8) -> 0 | G9: =SUM(G2:G8) -> 0 | H9: =SUM(H2:H8) -> 0 | I9: =SUM(I2:I8) -> 0 | ... W9: =SUM(W2:W8) -> 0
A10: Expense Item | B10: 1 | C10: 2 | D10: 3 | E10: 4 | F10: 5 | G10: 6 | H10: 7 | I10: 8 | J10: 9 | K10: 10 | L10: 11 | M10: 12 | N10: 13 | O10: 14 | P10: 15 | Q10: 16 | R10: 17 | S10: 18 | T10: 19 | U10: 20 | V10: Total
A11: ='Dashboard-Jan'!$C14 -> Reward-1 | V11: =('Dashboard-Jan'!D14)*(SUM(B11:U11)) -> 0
A12: ='Dashboard-Jan'!$C15 -> Reward-2 | V12: =('Dashboard-Jan'!D15)*(SUM(B12:U12)) -> 0
A13: ='Dashboard-Jan'!$C16 -> Reward-3 | V13: =('Dashboard-Jan'!D16)*(SUM(B13:U13)) -> 0
A14: TOTAL | B14: =SUM(B11:B13) -> 0 | C14: =SUM(C11:C13) -> 0 | D14: =SUM(D11:D13) -> 0 | E14: =SUM(E11:E13) -> 0 | F14: =SUM(F11:F13) -> 0 | G14: =SUM(G11:G13) -> 0 | H14: =SUM(H11:H13) -> 0 | I14: =SUM(I11:I13) -> 0 | ... V14: =SUM(V11:V13) -> 0

Sheet 5
A1: Task Name | B1: 1 | C1: 2 | D1: 3 | E1: 4 | F1: 5 | G1: 6 | H1: 7 | I1: 8 | J1: 9 | K1: 10 | L1: 11 | M1: 12 | N1: 13 | O1: 14 | P1: 15 | Q1: 16 | R1: 17 | S1: 18 | T1: 19 | U1: 20 | V1: Total | W1: Streak
A2: ='Dashboard-Jan'!$C2 -> Task-1 | V2: =(('Dashboard-Jan'!D2)*(SUM(B2:U2)))*((W2*'Dashboard-Jan'!$D$10)+1) -> 0 | W2: =IF('4'!V2 <> 0,('4'!W2)+1,0) -> 0
A3: ='Dashboard-Jan'!$C3 -> Task-2 | V3: =(('Dashboard-Jan'!D3)*(SUM(B3:U3)))*((W3*'Dashboard-Jan'!$D$10)+1) -> 0 | W3: =IF('4'!V3 <> 0,('4'!W3)+1,0) -> 0
A4: ='Dashboard-Jan'!$C4 -> Task-3 | V4: =(('Dashboard-Jan'!D4)*(SUM(B4:U4)))*((W4*'Dashboard-Jan'!$D$10)+1) -> 0 | W4: =IF('4'!V4 <> 0,('4'!W4)+1,0) -> 0
A5: ='Dashboard-Jan'!$C5 -> Task-4 | V5: =(('Dashboard-Jan'!D5)*(SUM(B5:U5)))*((W5*'Dashboard-Jan'!$D$10)+1) -> 0 | W5: =IF('4'!V5 <> 0,('4'!W5)+1,0) -> 0
A6: ='Dashboard-Jan'!$C6 -> Task-5 | V6: =(('Dashboard-Jan'!D6)*(SUM(B6:U6)))*((W6*'Dashboard-Jan'!$D$10)+1) -> 0 | W6: =IF('4'!V6 <> 0,('4'!W6)+1,0) -> 0
A7: ='Dashboard-Jan'!$C7 -> Task-6 | V7: =(('Dashboard-Jan'!D7)*(SUM(B7:U7)))*((W7*'Dashboard-Jan'!$D$10)+1) -> 0 | W7: =IF('4'!V7 <> 0,('4'!W7)+1,0) -> 0
A8: ='Dashboard-Jan'!$C8 -> Task-7 | V8: =(('Dashboard-Jan'!D8)*(SUM(B8:U8)))*((W8*'Dashboard-Jan'!$D$10)+1) -> 0 | W8: =IF('4'!V8 <> 0,('4'!W8)+1,0) -> 0
A9: TOTAL | B9: =SUM(B2:B8) -> 0 | C9: =SUM(C2:C8) -> 0 | D9: =SUM(D2:D8) -> 0 | E9: =SUM(E2:E8) -> 0 | F9: =SUM(F2:F8) -> 0 | G9: =SUM(G2:G8) -> 0 | H9: =SUM(H2:H8) -> 0 | I9: =SUM(I2:I8) -> 0 | ... W9: =SUM(W2:W8) -> 0
A10: Expense Item | B10: 1 | C10: 2 | D10: 3 | E10: 4 | F10: 5 | G10: 6 | H10: 7 | I10: 8 | J10: 9 | K10: 10 | L10: 11 | M10: 12 | N10: 13 | O10: 14 | P10: 15 | Q10: 16 | R10: 17 | S10: 18 | T10: 19 | U10: 20 | V10: Total
A11: ='Dashboard-Jan'!$C14 -> Reward-1 | V11: =('Dashboard-Jan'!D14)*(SUM(B11:U11)) -> 0
A12: ='Dashboard-Jan'!$C15 -> Reward-2 | V12: =('Dashboard-Jan'!D15)*(SUM(B12:U12)) -> 0
A13: ='Dashboard-Jan'!$C16 -> Reward-3 | V13: =('Dashboard-Jan'!D16)*(SUM(B13:U13)) -> 0
A14: TOTAL | B14: =SUM(B11:B13) -> 0 | C14: =SUM(C11:C13) -> 0 | D14: =SUM(D11:D13) -> 0 | E14: =SUM(E11:E13) -> 0 | F14: =SUM(F11:F13) -> 0 | G14: =SUM(G11:G13) -> 0 | H14: =SUM(H11:H13) -> 0 | I14: =SUM(I11:I13) -> 0 | ... V14: =SUM(V11:V13) -> 0

Sheet 6
A1: Task Name | B1: 1 | C1: 2 | D1: 3 | E1: 4 | F1: 5 | G1: 6 | H1: 7 | I1: 8 | J1: 9 | K1: 10 | L1: 11 | M1: 12 | N1: 13 | O1: 14 | P1: 15 | Q1: 16 | R1: 17 | S1: 18 | T1: 19 | U1: 20 | V1: Total | W1: Streak
A2: ='Dashboard-Jan'!$C2 -> Task-1 | V2: =(('Dashboard-Jan'!D2)*(SUM(B2:U2)))*((W2*'Dashboard-Jan'!$D$10)+1) -> 0 | W2: =IF('5'!V2 <> 0,('5'!W2)+1,0) -> 0
A3: ='Dashboard-Jan'!$C3 -> Task-2 | V3: =(('Dashboard-Jan'!D3)*(SUM(B3:U3)))*((W3*'Dashboard-Jan'!$D$10)+1) -> 0 | W3: =IF('5'!V3 <> 0,('5'!W3)+1,0) -> 0
A4: ='Dashboard-Jan'!$C4 -> Task-3 | V4: =(('Dashboard-Jan'!D4)*(SUM(B4:U4)))*((W4*'Dashboard-Jan'!$D$10)+1) -> 0 | W4: =IF('5'!V4 <> 0,('5'!W4)+1,0) -> 0
A5: ='Dashboard-Jan'!$C5 -> Task-4 | V5: =(('Dashboard-Jan'!D5)*(SUM(B5:U5)))*((W5*'Dashboard-Jan'!$D$10)+1) -> 0 | W5: =IF('5'!V5 <> 0,('5'!W5)+1,0) -> 0
A6: ='Dashboard-Jan'!$C6 -> Task-5 | V6: =(('Dashboard-Jan'!D6)*(SUM(B6:U6)))*((W6*'Dashboard-Jan'!$D$10)+1) -> 0 | W6: =IF('5'!V6 <> 0,('5'!W6)+1,0) -> 0
A7: ='Dashboard-Jan'!$C7 -> Task-6 | V7: =(('Dashboard-Jan'!D7)*(SUM(B7:U7)))*((W7*'Dashboard-Jan'!$D$10)+1) -> 0 | W7: =IF('5'!V7 <> 0,('5'!W7)+1,0) -> 0
A8: ='Dashboard-Jan'!$C8 -> Task-7 | V8: =(('Dashboard-Jan'!D8)*(SUM(B8:U8)))*((W8*'Dashboard-Jan'!$D$10)+1) -> 0 | W8: =IF('5'!V8 <> 0,('5'!W8)+1,0) -> 0
A9: TOTAL | B9: =SUM(B2:B8) -> 0 | C9: =SUM(C2:C8) -> 0 | D9: =SUM(D2:D8) -> 0 | E9: =SUM(E2:E8) -> 0 | F9: =SUM(F2:F8) -> 0 | G9: =SUM(G2:G8) -> 0 | H9: =SUM(H2:H8) -> 0 | I9: =SUM(I2:I8) -> 0 | ... W9: =SUM(W2:W8) -> 0
A10: Expense Item | B10: 1 | C10: 2 | D10: 3 | E10: 4 | F10: 5 | G10: 6 | H10: 7 | I10: 8 | J10: 9 | K10: 10 | L10: 11 | M10: 12 | N10: 13 | O10: 14 | P10: 15 | Q10: 16 | R10: 17 | S10: 18 | T10: 19 | U10: 20 | V10: Total
A11: ='Dashboard-Jan'!$C14 -> Reward-1 | V11: =('Dashboard-Jan'!D14)*(SUM(B11:U11)) -> 0
A12: ='Dashboard-Jan'!$C15 -> Reward-2 | V12: =('Dashboard-Jan'!D15)*(SUM(B12:U12)) -> 0
A13: ='Dashboard-Jan'!$C16 -> Reward-3 | V13: =('Dashboard-Jan'!D16)*(SUM(B13:U13)) -> 0
A14: TOTAL | B14: =SUM(B11:B13) -> 0 | C14: =SUM(C11:C13) -> 0 | D14: =SUM(D11:D13) -> 0 | E14: =SUM(E11:E13) -> 0 | F14: =SUM(F11:F13) -> 0 | G14: =SUM(G11:G13) -> 0 | H14: =SUM(H11:H13) -> 0 | I14: =SUM(I11:I13) -> 0 | ... V14: =SUM(V11:V13) -> 0

Sheet 7
A1: Task Name | B1: 1 | C1: 2 | D1: 3 | E1: 4 | F1: 5 | G1: 6 | H1: 7 | I1: 8 | J1: 9 | K1: 10 | L1: 11 | M1: 12 | N1: 13 | O1: 14 | P1: 15 | Q1: 16 | R1: 17 | S1: 18 | T1: 19 | U1: 20 | V1: Total | W1: Streak
A2: ='Dashboard-Jan'!$C2 -> Task-1 | V2: =(('Dashboard-Jan'!D2)*(SUM(B2:U2)))*((W2*'Dashboard-Jan'!$D$10)+1) -> 0 | W2: =IF('6'!V2 <> 0,('6'!W2)+1,0) -> 0
A3: ='Dashboard-Jan'!$C3 -> Task-2 | V3: =(('Dashboard-Jan'!D3)*(SUM(B3:U3)))*((W3*'Dashboard-Jan'!$D$10)+1) -> 0 | W3: =IF('6'!V3 <> 0,('6'!W3)+1,0) -> 0
A4: ='Dashboard-Jan'!$C4 -> Task-3 | V4: =(('Dashboard-Jan'!D4)*(SUM(B4:U4)))*((W4*'Dashboard-Jan'!$D$10)+1) -> 0 | W4: =IF('6'!V4 <> 0,('6'!W4)+1,0) -> 0
A5: ='Dashboard-Jan'!$C5 -> Task-4 | V5: =(('Dashboard-Jan'!D5)*(SUM(B5:U5)))*((W5*'Dashboard-Jan'!$D$10)+1) -> 0 | W5: =IF('6'!V5 <> 0,('6'!W5)+1,0) -> 0
A6: ='Dashboard-Jan'!$C6 -> Task-5 | V6: =(('Dashboard-Jan'!D6)*(SUM(B6:U6)))*((W6*'Dashboard-Jan'!$D$10)+1) -> 0 | W6: =IF('6'!V6 <> 0,('6'!W6)+1,0) -> 0
A7: ='Dashboard-Jan'!$C7 -> Task-6 | V7: =(('Dashboard-Jan'!D7)*(SUM(B7:U7)))*((W7*'Dashboard-Jan'!$D$10)+1) -> 0 | W7: =IF('6'!V7 <> 0,('6'!W7)+1,0) -> 0
A8: ='Dashboard-Jan'!$C8 -> Task-7 | V8: =(('Dashboard-Jan'!D8)*(SUM(B8:U8)))*((W8*'Dashboard-Jan'!$D$10)+1) -> 0 | W8: =IF('6'!V8 <> 0,('6'!W8)+1,0) -> 0
A9: TOTAL | B9: =SUM(B2:B8) -> 0 | C9: =SUM(C2:C8) -> 0 | D9: =SUM(D2:D8) -> 0 | E9: =SUM(E2:E8) -> 0 | F9: =SUM(F2:F8) -> 0 | G9: =SUM(G2:G8) -> 0 | H9: =SUM(H2:H8) -> 0 | I9: =SUM(I2:I8) -> 0 | ... W9: =SUM(W2:W8) -> 0
A10: Expense Item | B10: 1 | C10: 2 | D10: 3 | E10: 4 | F10: 5 | G10: 6 | H10: 7 | I10: 8 | J10: 9 | K10: 10 | L10: 11 | M10: 12 | N10: 13 | O10: 14 | P10: 15 | Q10: 16 | R10: 17 | S10: 18 | T10: 19 | U10: 20 | V10: Total
A11: ='Dashboard-Jan'!$C14 -> Reward-1 | V11: =('Dashboard-Jan'!D14)*(SUM(B11:U11)) -> 0
A12: ='Dashboard-Jan'!$C15 -> Reward-2 | V12: =('Dashboard-Jan'!D15)*(SUM(B12:U12)) -> 0
A13: ='Dashboard-Jan'!$C16 -> Reward-3 | V13: =('Dashboard-Jan'!D16)*(SUM(B13:U13)) -> 0
A14: TOTAL | B14: =SUM(B11:B13) -> 0 | C14: =SUM(C11:C13) -> 0 | D14: =SUM(D11:D13) -> 0 | E14: =SUM(E11:E13) -> 0 | F14: =SUM(F11:F13) -> 0 | G14: =SUM(G11:G13) -> 0 | H14: =SUM(H11:H13) -> 0 | I14: =SUM(I11:I13) -> 0 | ... V14: =SUM(V11:V13) -> 0

Sheet 8
A1: 8 | B1: 1 | C1: 2 | D1: 3 | E1: 4 | F1: 5 | G1: 6 | H1: 7 | I1: 8 | J1: 9 | K1: 10 | L1: 11 | M1: 12 | N1: 13 | O1: 14 | P1: 15 | Q1: 16 | R1: 17 | S1: 18 | T1: 19 | U1: 20 | V1: Total | W1: Streak
A2: ='Dashboard-Jan'!$C2 -> Task-1 | V2: =(('Dashboard-Jan'!D2)*(SUM(B2:U2)))*((W2*'Dashboard-Jan'!$D$10)+1) -> 0 | W2: =IF('7'!V2 <> 0,('7'!W2)+1,0) -> 0
A3: ='Dashboard-Jan'!$C3 -> Task-2 | V3: =(('Dashboard-Jan'!D3)*(SUM(B3:U3)))*((W3*'Dashboard-Jan'!$D$10)+1) -> 0 | W3: =IF('7'!V3 <> 0,('7'!W3)+1,0) -> 0
A4: ='Dashboard-Jan'!$C4 -> Task-3 | V4: =(('Dashboard-Jan'!D4)*(SUM(B4:U4)))*((W4*'Dashboard-Jan'!$D$10)+1) -> 0 | W4: =IF('7'!V4 <> 0,('7'!W4)+1,0) -> 0
A5: ='Dashboard-Jan'!$C5 -> Task-4 | V5: =(('Dashboard-Jan'!D5)*(SUM(B5:U5)))*((W5*'Dashboard-Jan'!$D$10)+1) -> 0 | W5: =IF('7'!V5 <> 0,('7'!W5)+1,0) -> 0
A6: ='Dashboard-Jan'!$C6 -> Task-5 | V6: =(('Dashboard-Jan'!D6)*(SUM(B6:U6)))*((W6*'Dashboard-Jan'!$D$10)+1) -> 0 | W6: =IF('7'!V6 <> 0,('7'!W6)+1,0) -> 0
A7: ='Dashboard-Jan'!$C7 -> Task-6 | V7: =(('Dashboard-Jan'!D7)*(SUM(B7:U7)))*((W7*'Dashboard-Jan'!$D$10)+1) -> 0 | W7: =IF('7'!V7 <> 0,('7'!W7)+1,0) -> 0
A8: ='Dashboard-Jan'!$C8 -> Task-7 | V8: =(('Dashboard-Jan'!D8)*(SUM(B8:U8)))*((W8*'Dashboard-Jan'!$D$10)+1) -> 0 | W8: =IF('7'!V8 <> 0,('7'!W8)+1,0) -> 0
A9: TOTAL | B9: =SUM(B2:B8) -> 0 | C9: =SUM(C2:C8) -> 0 | D9: =SUM(D2:D8) -> 0 | E9: =SUM(E2:E8) -> 0 | F9: =SUM(F2:F8) -> 0 | G9: =SUM(G2:G8) -> 0 | H9: =SUM(H2:H8) -> 0 | I9: =SUM(I2:I8) -> 0 | ... W9: =SUM(W2:W8) -> 0
A10: Expense Item | B10: 1 | C10: 2 | D10: 3 | E10: 4 | F10: 5 | G10: 6 | H10: 7 | I10: 8 | J10: 9 | K10: 10 | L10: 11 | M10: 12 | N10: 13 | O10: 14 | P10: 15 | Q10: 16 | R10: 17 | S10: 18 | T10: 19 | U10: 20 | V10: Total
A11: ='Dashboard-Jan'!$C14 -> Reward-1 | V11: =('Dashboard-Jan'!D14)*(SUM(B11:U11)) -> 0
A12: ='Dashboard-Jan'!$C15 -> Reward-2 | V12: =('Dashboard-Jan'!D15)*(SUM(B12:U12)) -> 0
A13: ='Dashboard-Jan'!$C16 -> Reward-3 | V13: =('Dashboard-Jan'!D16)*(SUM(B13:U13)) -> 0
A14: TOTAL | B14: =SUM(B11:B13) -> 0 | C14: =SUM(C11:C13) -> 0 | D14: =SUM(D11:D13) -> 0 | E14: =SUM(E11:E13) -> 0 | F14: =SUM(F11:F13) -> 0 | G14: =SUM(G11:G13) -> 0 | H14: =SUM(H11:H13) -> 0 | I14: =SUM(I11:I13) -> 0 | ... V14: =SUM(V11:V13) -> 0

Sheet 9
A1: Task Name | B1: 1 | C1: 2 | D1: 3 | E1: 4 | F1: 5 | G1: 6 | H1: 7 | I1: 8 | J1: 9 | K1: 10 | L1: 11 | M1: 12 | N1: 13 | O1: 14 | P1: 15 | Q1: 16 | R1: 17 | S1: 18 | T1: 19 | U1: 20 | V1: Total | W1: Streak
A2: ='Dashboard-Jan'!$C2 -> Task-1 | V2: =(('Dashboard-Jan'!D2)*(SUM(B2:U2)))*((W2*'Dashboard-Jan'!$D$10)+1) -> 0 | W2: =IF('8'!V2 <> 0,('8'!W2)+1,0) -> 0
A3: ='Dashboard-Jan'!$C3 -> Task-2 | V3: =(('Dashboard-Jan'!D3)*(SUM(B3:U3)))*((W3*'Dashboard-Jan'!$D$10)+1) -> 0 | W3: =IF('8'!V3 <> 0,('8'!W3)+1,0) -> 0
A4: ='Dashboard-Jan'!$C4 -> Task-3 | V4: =(('Dashboard-Jan'!D4)*(SUM(B4:U4)))*((W4*'Dashboard-Jan'!$D$10)+1) -> 0 | W4: =IF('8'!V4 <> 0,('8'!W4)+1,0) -> 0
A5: ='Dashboard-Jan'!$C5 -> Task-4 | V5: =(('Dashboard-Jan'!D5)*(SUM(B5:U5)))*((W5*'Dashboard-Jan'!$D$10)+1) -> 0 | W5: =IF('8'!V5 <> 0,('8'!W5)+1,0) -> 0
A6: ='Dashboard-Jan'!$C6 -> Task-5 | V6: =(('Dashboard-Jan'!D6)*(SUM(B6:U6)))*((W6*'Dashboard-Jan'!$D$10)+1) -> 0 | W6: =IF('8'!V6 <> 0,('8'!W6)+1,0) -> 0
A7: ='Dashboard-Jan'!$C7 -> Task-6 | V7: =(('Dashboard-Jan'!D7)*(SUM(B7:U7)))*((W7*'Dashboard-Jan'!$D$10)+1) -> 0 | W7: =IF('8'!V7 <> 0,('8'!W7)+1,0) -> 0
A8: ='Dashboard-Jan'!$C8 -> Task-7 | V8: =(('Dashboard-Jan'!D8)*(SUM(B8:U8)))*((W8*'Dashboard-Jan'!$D$10)+1) -> 0 | W8: =IF('8'!V8 <> 0,('8'!W8)+1,0) -> 0
A9: TOTAL | B9: =SUM(B2:B8) -> 0 | C9: =SUM(C2:C8) -> 0 | D9: =SUM(D2:D8) -> 0 | E9: =SUM(E2:E8) -> 0 | F9: =SUM(F2:F8) -> 0 | G9: =SUM(G2:G8) -> 0 | H9: =SUM(H2:H8) -> 0 | I9: =SUM(I2:I8) -> 0 | ... W9: =SUM(W2:W8) -> 0
A10: Expense Item | B10: 1 | C10: 2 | D10: 3 | E10: 4 | F10: 5 | G10: 6 | H10: 7 | I10: 8 | J10: 9 | K10: 10 | L10: 11 | M10: 12 | N10: 13 | O10: 14 | P10: 15 | Q10: 16 | R10: 17 | S10: 18 | T10: 19 | U10: 20 | V10: Total
A11: ='Dashboard-Jan'!$C14 -> Reward-1 | V11: =('Dashboard-Jan'!D14)*(SUM(B11:U11)) -> 0
A12: ='Dashboard-Jan'!$C15 -> Reward-2 | V12: =('Dashboard-Jan'!D15)*(SUM(B12:U12)) -> 0
A13: ='Dashboard-Jan'!$C16 -> Reward-3 | V13: =('Dashboard-Jan'!D16)*(SUM(B13:U13)) -> 0
A14: TOTAL | B14: =SUM(B11:B13) -> 0 | C14: =SUM(C11:C13) -> 0 | D14: =SUM(D11:D13) -> 0 | E14: =SUM(E11:E13) -> 0 | F14: =SUM(F11:F13) -> 0 | G14: =SUM(G11:G13) -> 0 | H14: =SUM(H11:H13) -> 0 | I14: =SUM(I11:I13) -> 0 | ... V14: =SUM(V11:V13) -> 0

Sheet 10
A1: Task Name | B1: 1 | C1: 2 | D1: 3 | E1: 4 | F1: 5 | G1: 6 | H1: 7 | I1: 8 | J1: 9 | K1: 10 | L1: 11 | M1: 12 | N1: 13 | O1: 14 | P1: 15 | Q1: 16 | R1: 17 | S1: 18 | T1: 19 | U1: 20 | V1: Total | W1: Streak
A2: ='Dashboard-Jan'!$C2 -> Task-1 | V2: =(('Dashboard-Jan'!D2)*(SUM(B2:U2)))*((W2*'Dashboard-Jan'!$D$10)+1) -> 0 | W2: =IF('9'!V2 <> 0,('9'!W2)+1,0) -> 0
A3: ='Dashboard-Jan'!$C3 -> Task-2 | V3: =(('Dashboard-Jan'!D3)*(SUM(B3:U3)))*((W3*'Dashboard-Jan'!$D$10)+1) -> 0 | W3: =IF('9'!V3 <> 0,('9'!W3)+1,0) -> 0
A4: ='Dashboard-Jan'!$C4 -> Task-3 | V4: =(('Dashboard-Jan'!D4)*(SUM(B4:U4)))*((W4*'Dashboard-Jan'!$D$10)+1) -> 0 | W4: =IF('9'!V4 <> 0,('9'!W4)+1,0) -> 0
A5: ='Dashboard-Jan'!$C5 -> Task-4 | V5: =(('Dashboard-Jan'!D5)*(SUM(B5:U5)))*((W5*'Dashboard-Jan'!$D$10)+1) -> 0 | W5: =IF('9'!V5 <> 0,('9'!W5)+1,0) -> 0
A6: ='Dashboard-Jan'!$C6 -> Task-5 | V6: =(('Dashboard-Jan'!D6)*(SUM(B6:U6)))*((W6*'Dashboard-Jan'!$D$10)+1) -> 0 | W6: =IF('9'!V6 <> 0,('9'!W6)+1,0) -> 0
A7: ='Dashboard-Jan'!$C7 -> Task-6 | V7: =(('Dashboard-Jan'!D7)*(SUM(B7:U7)))*((W7*'Dashboard-Jan'!$D$10)+1) -> 0 | W7: =IF('9'!V7 <> 0,('9'!W7)+1,0) -> 0
A8: ='Dashboard-Jan'!$C8 -> Task-7 | V8: =(('Dashboard-Jan'!D8)*(SUM(B8:U8)))*((W8*'Dashboard-Jan'!$D$10)+1) -> 0 | W8: =IF('9'!V8 <> 0,('9'!W8)+1,0) -> 0
A9: TOTAL | B9: =SUM(B2:B8) -> 0 | C9: =SUM(C2:C8) -> 0 | D9: =SUM(D2:D8) -> 0 | E9: =SUM(E2:E8) -> 0 | F9: =SUM(F2:F8) -> 0 | G9: =SUM(G2:G8) -> 0 | H9: =SUM(H2:H8) -> 0 | I9: =SUM(I2:I8) -> 0 | ... W9: =SUM(W2:W8) -> 0
A10: Expense Item | B10: 1 | C10: 2 | D10: 3 | E10: 4 | F10: 5 | G10: 6 | H10: 7 | I10: 8 | J10: 9 | K10: 10 | L10: 11 | M10: 12 | N10: 13 | O10: 14 | P10: 15 | Q10: 16 | R10: 17 | S10: 18 | T10: 19 | U10: 20 | V10: Total
A11: ='Dashboard-Jan'!$C14 -> Reward-1 | V11: =('Dashboard-Jan'!D14)*(SUM(B11:U11)) -> 0
A12: ='Dashboard-Jan'!$C15 -> Reward-2 | V12: =('Dashboard-Jan'!D15)*(SUM(B12:U12)) -> 0
A13: ='Dashboard-Jan'!$C16 -> Reward-3 | V13: =('Dashboard-Jan'!D16)*(SUM(B13:U13)) -> 0
A14: TOTAL | B14: =SUM(B11:B13) -> 0 | C14: =SUM(C11:C13) -> 0 | D14: =SUM(D11:D13) -> 0 | E14: =SUM(E11:E13) -> 0 | F14: =SUM(F11:F13) -> 0 | G14: =SUM(G11:G13) -> 0 | H14: =SUM(H11:H13) -> 0 | I14: =SUM(I11:I13) -> 0 | ... V14: =SUM(V11:V13) -> 0

Sheet 11
A1: Task Name | B1: 1 | C1: 2 | D1: 3 | E1: 4 | F1: 5 | G1: 6 | H1: 7 | I1: 8 | J1: 9 | K1: 10 | L1: 11 | M1: 12 | N1: 13 | O1: 14 | P1: 15 | Q1: 16 | R1: 17 | S1: 18 | T1: 19 | U1: 20 | V1: Total | W1: Streak
A2: ='Dashboard-Jan'!$C2 -> Task-1 | V2: =(('Dashboard-Jan'!D2)*(SUM(B2:U2)))*((W2*'Dashboard-Jan'!$D$10)+1) -> 0 | W2: =IF('10'!V2 <> 0,('10'!W2)+1,0) -> 0
A3: ='Dashboard-Jan'!$C3 -> Task-2 | V3: =(('Dashboard-Jan'!D3)*(SUM(B3:U3)))*((W3*'Dashboard-Jan'!$D$10)+1) -> 0 | W3: =IF('10'!V3 <> 0,('10'!W3)+1,0) -> 0
A4: ='Dashboard-Jan'!$C4 -> Task-3 | V4: =(('Dashboard-Jan'!D4)*(SUM(B4:U4)))*((W4*'Dashboard-Jan'!$D$10)+1) -> 0 | W4: =IF('10'!V4 <> 0,('10'!W4)+1,0) -> 0
A5: ='Dashboard-Jan'!$C5 -> Task-4 | V5: =(('Dashboard-Jan'!D5)*(SUM(B5:U5)))*((W5*'Dashboard-Jan'!$D$10)+1) -> 0 | W5: =IF('10'!V5 <> 0,('10'!W5)+1,0) -> 0
A6: ='Dashboard-Jan'!$C6 -> Task-5 | V6: =(('Dashboard-Jan'!D6)*(SUM(B6:U6)))*((W6*'Dashboard-Jan'!$D$10)+1) -> 0 | W6: =IF('10'!V6 <> 0,('10'!W6)+1,0) -> 0
A7: ='Dashboard-Jan'!$C7 -> Task-6 | V7: =(('Dashboard-Jan'!D7)*(SUM(B7:U7)))*((W7*'Dashboard-Jan'!$D$10)+1) -> 0 | W7: =IF('10'!V7 <> 0,('10'!W7)+1,0) -> 0
A8: ='Dashboard-Jan'!$C8 -> Task-7 | V8: =(('Dashboard-Jan'!D8)*(SUM(B8:U8)))*((W8*'Dashboard-Jan'!$D$10)+1) -> 0 | W8: =IF('10'!V8 <> 0,('10'!W8)+1,0) -> 0
A9: TOTAL | B9: =SUM(B2:B8) -> 0 | C9: =SUM(C2:C8) -> 0 | D9: =SUM(D2:D8) -> 0 | E9: =SUM(E2:E8) -> 0 | F9: =SUM(F2:F8) -> 0 | G9: =SUM(G2:G8) -> 0 | H9: =SUM(H2:H8) -> 0 | I9: =SUM(I2:I8) -> 0 | ... W9: =SUM(W2:W8) -> 0
A10: Expense Item | B10: 1 | C10: 2 | D10: 3 | E10: 4 | F10: 5 | G10: 6 | H10: 7 | I10: 8 | J10: 9 | K10: 10 | L10: 11 | M10: 12 | N10: 13 | O10: 14 | P10: 15 | Q10: 16 | R10: 17 | S10: 18 | T10: 19 | U10: 20 | V10: Total
A11: ='Dashboard-Jan'!$C14 -> Reward-1 | V11: =('Dashboard-Jan'!D14)*(SUM(B11:U11)) -> 0
A12: ='Dashboard-Jan'!$C15 -> Reward-2 | V12: =('Dashboard-Jan'!D15)*(SUM(B12:U12)) -> 0
A13: ='Dashboard-Jan'!$C16 -> Reward-3 | V13: =('Dashboard-Jan'!D16)*(SUM(B13:U13)) -> 0
A14: TOTAL | B14: =SUM(B11:B13) -> 0 | C14: =SUM(C11:C13) -> 0 | D14: =SUM(D11:D13) -> 0 | E14: =SUM(E11:E13) -> 0 | F14: =SUM(F11:F13) -> 0 | G14: =SUM(G11:G13) -> 0 | H14: =SUM(H11:H13) -> 0 | I14: =SUM(I11:I13) -> 0 | ... V14: =SUM(V11:V13) -> 0

Sheet 12
A1: Task Name | B1: 1 | C1: 2 | D1: 3 | E1: 4 | F1: 5 | G1: 6 | H1: 7 | I1: 8 | J1: 9 | K1: 10 | L1: 11 | M1: 12 | N1: 13 | O1: 14 | P1: 15 | Q1: 16 | R1: 17 | S1: 18 | T1: 19 | U1: 20 | V1: Total | W1: Streak
A2: ='Dashboard-Jan'!$C2 -> Task-1 | V2: =(('Dashboard-Jan'!D2)*(SUM(B2:U2)))*((W2*'Dashboard-Jan'!$D$10)+1) -> 0 | W2: =IF('11'!V2 <> 0,('11'!W2)+1,0) -> 0
A3: ='Dashboard-Jan'!$C3 -> Task-2 | V3: =(('Dashboard-Jan'!D3)*(SUM(B3:U3)))*((W3*'Dashboard-Jan'!$D$10)+1) -> 0 | W3: =IF('11'!V3 <> 0,('11'!W3)+1,0) -> 0
A4: ='Dashboard-Jan'!$C4 -> Task-3 | V4: =(('Dashboard-Jan'!D4)*(SUM(B4:U4)))*((W4*'Dashboard-Jan'!$D$10)+1) -> 0 | W4: =IF('11'!V4 <> 0,('11'!W4)+1,0) -> 0
A5: ='Dashboard-Jan'!$C5 -> Task-4 | V5: =(('Dashboard-Jan'!D5)*(SUM(B5:U5)))*((W5*'Dashboard-Jan'!$D$10)+1) -> 0 | W5: =IF('11'!V5 <> 0,('11'!W5)+1,0) -> 0
A6: ='Dashboard-Jan'!$C6 -> Task-5 | V6: =(('Dashboard-Jan'!D6)*(SUM(B6:U6)))*((W6*'Dashboard-Jan'!$D$10)+1) -> 0 | W6: =IF('11'!V6 <> 0,('11'!W6)+1,0) -> 0
A7: ='Dashboard-Jan'!$C7 -> Task-6 | V7: =(('Dashboard-Jan'!D7)*(SUM(B7:U7)))*((W7*'Dashboard-Jan'!$D$10)+1) -> 0 | W7: =IF('11'!V7 <> 0,('11'!W7)+1,0) -> 0
A8: ='Dashboard-Jan'!$C8 -> Task-7 | V8: =(('Dashboard-Jan'!D8)*(SUM(B8:U8)))*((W8*'Dashboard-Jan'!$D$10)+1) -> 0 | W8: =IF('11'!V8 <> 0,('11'!W8)+1,0) -> 0
A9: TOTAL | B9: =SUM(B2:B8) -> 0 | C9: =SUM(C2:C8) -> 0 | D9: =SUM(D2:D8) -> 0 | E9: =SUM(E2:E8) -> 0 | F9: =SUM(F2:F8) -> 0 | G9: =SUM(G2:G8) -> 0 | H9: =SUM(H2:H8) -> 0 | I9: =SUM(I2:I8) -> 0 | ... W9: =SUM(W2:W8) -> 0
A10: Expense Item | B10: 1 | C10: 2 | D10: 3 | E10: 4 | F10: 5 | G10: 6 | H10: 7 | I10: 8 | J10: 9 | K10: 10 | L10: 11 | M10: 12 | N10: 13 | O10: 14 | P10: 15 | Q10: 16 | R10: 17 | S10: 18 | T10: 19 | U10: 20 | V10: Total
A11: ='Dashboard-Jan'!$C14 -> Reward-1 | V11: =('Dashboard-Jan'!D14)*(SUM(B11:U11)) -> 0
A12: ='Dashboard-Jan'!$C15 -> Reward-2 | V12: =('Dashboard-Jan'!D15)*(SUM(B12:U12)) -> 0
A13: ='Dashboard-Jan'!$C16 -> Reward-3 | V13: =('Dashboard-Jan'!D16)*(SUM(B13:U13)) -> 0
A14: TOTAL | B14: =SUM(B11:B13) -> 0 | C14: =SUM(C11:C13) -> 0 | D14: =SUM(D11:D13) -> 0 | E14: =SUM(E11:E13) -> 0 | F14: =SUM(F11:F13) -> 0 | G14: =SUM(G11:G13) -> 0 | H14: =SUM(H11:H13) -> 0 | I14: =SUM(I11:I13) -> 0 | ... V14: =SUM(V11:V13) -> 0

Sheet 13
A1: 13 | B1: 1 | C1: 2 | D1: 3 | E1: 4 | F1: 5 | G1: 6 | H1: 7 | I1: 8 | J1: 9 | K1: 10 | L1: 11 | M1: 12 | N1: 13 | O1: 14 | P1: 15 | Q1: 16 | R1: 17 | S1: 18 | T1: 19 | U1: 20 | V1: Total | W1: Streak
A2: ='Dashboard-Jan'!$C2 -> Task-1 | V2: =(('Dashboard-Jan'!D2)*(SUM(B2:U2)))*((W2*'Dashboard-Jan'!$D$10)+1) -> 0 | W2: =IF('12'!V2 <> 0,('12'!W2)+1,0) -> 0
A3: ='Dashboard-Jan'!$C3 -> Task-2 | V3: =(('Dashboard-Jan'!D3)*(SUM(B3:U3)))*((W3*'Dashboard-Jan'!$D$10)+1) -> 0 | W3: =IF('12'!V3 <> 0,('12'!W3)+1,0) -> 0
A4: ='Dashboard-Jan'!$C4 -> Task-3 | V4: =(('Dashboard-Jan'!D4)*(SUM(B4:U4)))*((W4*'Dashboard-Jan'!$D$10)+1) -> 0 | W4: =IF('12'!V4 <> 0,('12'!W4)+1,0) -> 0
A5: ='Dashboard-Jan'!$C5 -> Task-4 | V5: =(('Dashboard-Jan'!D5)*(SUM(B5:U5)))*((W5*'Dashboard-Jan'!$D$10)+1) -> 0 | W5: =IF('12'!V5 <> 0,('12'!W5)+1,0) -> 0
A6: ='Dashboard-Jan'!$C6 -> Task-5 | V6: =(('Dashboard-Jan'!D6)*(SUM(B6:U6)))*((W6*'Dashboard-Jan'!$D$10)+1) -> 0 | W6: =IF('12'!V6 <> 0,('12'!W6)+1,0) -> 0
A7: ='Dashboard-Jan'!$C7 -> Task-6 | V7: =(('Dashboard-Jan'!D7)*(SUM(B7:U7)))*((W7*'Dashboard-Jan'!$D$10)+1) -> 0 | W7: =IF('12'!V7 <> 0,('12'!W7)+1,0) -> 0
A8: ='Dashboard-Jan'!$C8 -> Task-7 | V8: =(('Dashboard-Jan'!D8)*(SUM(B8:U8)))*((W8*'Dashboard-Jan'!$D$10)+1) -> 0 | W8: =IF('12'!V8 <> 0,('12'!W8)+1,0) -> 0
A9: TOTAL | B9: =SUM(B2:B8) -> 0 | C9: =SUM(C2:C8) -> 0 | D9: =SUM(D2:D8) -> 0 | E9: =SUM(E2:E8) -> 0 | F9: =SUM(F2:F8) -> 0 | G9: =SUM(G2:G8) -> 0 | H9: =SUM(H2:H8) -> 0 | I9: =SUM(I2:I8) -> 0 | ... W9: =SUM(W2:W8) -> 0
A10: Expense Item | B10: 1 | C10: 2 | D10: 3 | E10: 4 | F10: 5 | G10: 6 | H10: 7 | I10: 8 | J10: 9 | K10: 10 | L10: 11 | M10: 12 | N10: 13 | O10: 14 | P10: 15 | Q10: 16 | R10: 17 | S10: 18 | T10: 19 | U10: 20 | V10: Total
A11: ='Dashboard-Jan'!$C14 -> Reward-1 | V11: =('Dashboard-Jan'!D14)*(SUM(B11:U11)) -> 0
A12: ='Dashboard-Jan'!$C15 -> Reward-2 | V12: =('Dashboard-Jan'!D15)*(SUM(B12:U12)) -> 0
A13: ='Dashboard-Jan'!$C16 -> Reward-3 | V13: =('Dashboard-Jan'!D16)*(SUM(B13:U13)) -> 0
A14: TOTAL | B14: =SUM(B11:B13) -> 0 | C14: =SUM(C11:C13) -> 0 | D14: =SUM(D11:D13) -> 0 | E14: =SUM(E11:E13) -> 0 | F14: =SUM(F11:F13) -> 0 | G14: =SUM(G11:G13) -> 0 | H14: =SUM(H11:H13) -> 0 | I14: =SUM(I11:I13) -> 0 | ... V14: =SUM(V11:V13) -> 0

Sheet 14
A1: Task Name | B1: 1 | C1: 2 | D1: 3 | E1: 4 | F1: 5 | G1: 6 | H1: 7 | I1: 8 | J1: 9 | K1: 10 | L1: 11 | M1: 12 | N1: 13 | O1: 14 | P1: 15 | Q1: 16 | R1: 17 | S1: 18 | T1: 19 | U1: 20 | V1: Total | W1: Streak
A2: ='Dashboard-Jan'!$C2 -> Task-1 | V2: =(('Dashboard-Jan'!D2)*(SUM(B2:U2)))*((W2*'Dashboard-Jan'!$D$10)+1) -> 0 | W2: =IF('13'!V2 <> 0,('13'!W2)+1,0) -> 0
A3: ='Dashboard-Jan'!$C3 -> Task-2 | V3: =(('Dashboard-Jan'!D3)*(SUM(B3:U3)))*((W3*'Dashboard-Jan'!$D$10)+1) -> 0 | W3: =IF('13'!V3 <> 0,('13'!W3)+1,0) -> 0
A4: ='Dashboard-Jan'!$C4 -> Task-3 | V4: =(('Dashboard-Jan'!D4)*(SUM(B4:U4)))*((W4*'Dashboard-Jan'!$D$10)+1) -> 0 | W4: =IF('13'!V4 <> 0,('13'!W4)+1,0) -> 0
A5: ='Dashboard-Jan'!$C5 -> Task-4 | V5: =(('Dashboard-Jan'!D5)*(SUM(B5:U5)))*((W5*'Dashboard-Jan'!$D$10)+1) -> 0 | W5: =IF('13'!V5 <> 0,('13'!W5)+1,0) -> 0
A6: ='Dashboard-Jan'!$C6 -> Task-5 | V6: =(('Dashboard-Jan'!D6)*(SUM(B6:U6)))*((W6*'Dashboard-Jan'!$D$10)+1) -> 0 | W6: =IF('13'!V6 <> 0,('13'!W6)+1,0) -> 0
A7: ='Dashboard-Jan'!$C7 -> Task-6 | V7: =(('Dashboard-Jan'!D7)*(SUM(B7:U7)))*((W7*'Dashboard-Jan'!$D$10)+1) -> 0 | W7: =IF('13'!V7 <> 0,('13'!W7)+1,0) -> 0
A8: ='Dashboard-Jan'!$C8 -> Task-7 | V8: =(('Dashboard-Jan'!D8)*(SUM(B8:U8)))*((W8*'Dashboard-Jan'!$D$10)+1) -> 0 | W8: =IF('13'!V8 <> 0,('13'!W8)+1,0) -> 0
A9: TOTAL | B9: =SUM(B2:B8) -> 0 | C9: =SUM(C2:C8) -> 0 | D9: =SUM(D2:D8) -> 0 | E9: =SUM(E2:E8) -> 0 | F9: =SUM(F2:F8) -> 0 | G9: =SUM(G2:G8) -> 0 | H9: =SUM(H2:H8) -> 0 | I9: =SUM(I2:I8) -> 0 | ... W9: =SUM(W2:W8) -> 0
A10: Expense Item | B10: 1 | C10: 2 | D10: 3 | E10: 4 | F10: 5 | G10: 6 | H10: 7 | I10: 8 | J10: 9 | K10: 10 | L10: 11 | M10: 12 | N10: 13 | O10: 14 | P10: 15 | Q10: 16 | R10: 17 | S10: 18 | T10: 19 | U10: 20 | V10: Total
A11: ='Dashboard-Jan'!$C14 -> Reward-1 | V11: =('Dashboard-Jan'!D14)*(SUM(B11:U11)) -> 0
A12: ='Dashboard-Jan'!$C15 -> Reward-2 | V12: =('Dashboard-Jan'!D15)*(SUM(B12:U12)) -> 0
A13: ='Dashboard-Jan'!$C16 -> Reward-3 | V13: =('Dashboard-Jan'!D16)*(SUM(B13:U13)) -> 0
A14: TOTAL | B14: =SUM(B11:B13) -> 0 | C14: =SUM(C11:C13) -> 0 | D14: =SUM(D11:D13) -> 0 | E14: =SUM(E11:E13) -> 0 | F14: =SUM(F11:F13) -> 0 | G14: =SUM(G11:G13) -> 0 | H14: =SUM(H11:H13) -> 0 | I14: =SUM(I11:I13) -> 0 | ... V14: =SUM(V11:V13) -> 0

Sheet 15
A1: Task Name | B1: 1 | C1: 2 | D1: 3 | E1: 4 | F1: 5 | G1: 6 | H1: 7 | I1: 8 | J1: 9 | K1: 10 | L1: 11 | M1: 12 | N1: 13 | O1: 14 | P1: 15 | Q1: 16 | R1: 17 | S1: 18 | T1: 19 | U1: 20 | V1: Total | W1: Streak
A2: ='Dashboard-Jan'!$C2 -> Task-1 | V2: =(('Dashboard-Jan'!D2)*(SUM(B2:U2)))*((W2*'Dashboard-Jan'!$D$10)+1) -> 0 | W2: =IF('14'!V2 <> 0,('14'!W2)+1,0) -> 0
A3: ='Dashboard-Jan'!$C3 -> Task-2 | V3: =(('Dashboard-Jan'!D3)*(SUM(B3:U3)))*((W3*'Dashboard-Jan'!$D$10)+1) -> 0 | W3: =IF('14'!V3 <> 0,('14'!W3)+1,0) -> 0
A4: ='Dashboard-Jan'!$C4 -> Task-3 | V4: =(('Dashboard-Jan'!D4)*(SUM(B4:U4)))*((W4*'Dashboard-Jan'!$D$10)+1) -> 0 | W4: =IF('14'!V4 <> 0,('14'!W4)+1,0) -> 0
A5: ='Dashboard-Jan'!$C5 -> Task-4 | V5: =(('Dashboard-Jan'!D5)*(SUM(B5:U5)))*((W5*'Dashboard-Jan'!$D$10)+1) -> 0 | W5: =IF('14'!V5 <> 0,('14'!W5)+1,0) -> 0
A6: ='Dashboard-Jan'!$C6 -> Task-5 | V6: =(('Dashboard-Jan'!D6)*(SUM(B6:U6)))*((W6*'Dashboard-Jan'!$D$10)+1) -> 0 | W6: =IF('14'!V6 <> 0,('14'!W6)+1,0) -> 0
A7: ='Dashboard-Jan'!$C7 -> Task-6 | V7: =(('Dashboard-Jan'!D7)*(SUM(B7:U7)))*((W7*'Dashboard-Jan'!$D$10)+1) -> 0 | W7: =IF('14'!V7 <> 0,('14'!W7)+1,0) -> 0
A8: ='Dashboard-Jan'!$C8 -> Task-7 | V8: =(('Dashboard-Jan'!D8)*(SUM(B8:U8)))*((W8*'Dashboard-Jan'!$D$10)+1) -> 0 | W8: =IF('14'!V8 <> 0,('14'!W8)+1,0) -> 0
A9: TOTAL | B9: =SUM(B2:B8) -> 0 | C9: =SUM(C2:C8) -> 0 | D9: =SUM(D2:D8) -> 0 | E9: =SUM(E2:E8) -> 0 | F9: =SUM(F2:F8) -> 0 | G9: =SUM(G2:G8) -> 0 | H9: =SUM(H2:H8) -> 0 | I9: =SUM(I2:I8) -> 0 | ... W9: =SUM(W2:W8) -> 0
A10: Expense Item | B10: 1 | C10: 2 | D10: 3 | E10: 4 | F10: 5 | G10: 6 | H10: 7 | I10: 8 | J10: 9 | K10: 10 | L10: 11 | M10: 12 | N10: 13 | O10: 14 | P10: 15 | Q10: 16 | R10: 17 | S10: 18 | T10: 19 | U10: 20 | V10: Total
A11: ='Dashboard-Jan'!$C14 -> Reward-1 | V11: =('Dashboard-Jan'!D14)*(SUM(B11:U11)) -> 0
A12: ='Dashboard-Jan'!$C15 -> Reward-2 | V12: =('Dashboard-Jan'!D15)*(SUM(B12:U12)) -> 0
A13: ='Dashboard-Jan'!$C16 -> Reward-3 | V13: =('Dashboard-Jan'!D16)*(SUM(B13:U13)) -> 0
A14: TOTAL | B14: =SUM(B11:B13) -> 0 | C14: =SUM(C11:C13) -> 0 | D14: =SUM(D11:D13) -> 0 | E14: =SUM(E11:E13) -> 0 | F14: =SUM(F11:F13) -> 0 | G14: =SUM(G11:G13) -> 0 | H14: =SUM(H11:H13) -> 0 | I14: =SUM(I11:I13) -> 0 | ... V14: =SUM(V11:V13) -> 0

Sheet 16
A1: Task Name | B1: 1 | C1: 2 | D1: 3 | E1: 4 | F1: 5 | G1: 6 | H1: 7 | I1: 8 | J1: 9 | K1: 10 | L1: 11 | M1: 12 | N1: 13 | O1: 14 | P1: 15 | Q1: 16 | R1: 17 | S1: 18 | T1: 19 | U1: 20 | V1: Total | W1: Streak
A2: ='Dashboard-Jan'!$C2 -> Task-1 | V2: =(('Dashboard-Jan'!D2)*(SUM(B2:U2)))*((W2*'Dashboard-Jan'!$D$10)+1) -> 0 | W2: =IF('15'!V2 <> 0,('15'!W2)+1,0) -> 0
A3: ='Dashboard-Jan'!$C3 -> Task-2 | V3: =(('Dashboard-Jan'!D3)*(SUM(B3:U3)))*((W3*'Dashboard-Jan'!$D$10)+1) -> 0 | W3: =IF('15'!V3 <> 0,('15'!W3)+1,0) -> 0
A4: ='Dashboard-Jan'!$C4 -> Task-3 | V4: =(('Dashboard-Jan'!D4)*(SUM(B4:U4)))*((W4*'Dashboard-Jan'!$D$10)+1) -> 0 | W4: =IF('15'!V4 <> 0,('15'!W4)+1,0) -> 0
A5: ='Dashboard-Jan'!$C5 -> Task-4 | V5: =(('Dashboard-Jan'!D5)*(SUM(B5:U5)))*((W5*'Dashboard-Jan'!$D$10)+1) -> 0 | W5: =IF('15'!V5 <> 0,('15'!W5)+1,0) -> 0
A6: ='Dashboard-Jan'!$C6 -> Task-5 | V6: =(('Dashboard-Jan'!D6)*(SUM(B6:U6)))*((W6*'Dashboard-Jan'!$D$10)+1) -> 0 | W6: =IF('15'!V6 <> 0,('15'!W6)+1,0) -> 0
A7: ='Dashboard-Jan'!$C7 -> Task-6 | V7: =(('Dashboard-Jan'!D7)*(SUM(B7:U7)))*((W7*'Dashboard-Jan'!$D$10)+1) -> 0 | W7: =IF('15'!V7 <> 0,('15'!W7)+1,0) -> 0
A8: ='Dashboard-Jan'!$C8 -> Task-7 | V8: =(('Dashboard-Jan'!D8)*(SUM(B8:U8)))*((W8*'Dashboard-Jan'!$D$10)+1) -> 0 | W8: =IF('15'!V8 <> 0,('15'!W8)+1,0) -> 0
A9: TOTAL | B9: =SUM(B2:B8) -> 0 | C9: =SUM(C2:C8) -> 0 | D9: =SUM(D2:D8) -> 0 | E9: =SUM(E2:E8) -> 0 | F9: =SUM(F2:F8) -> 0 | G9: =SUM(G2:G8) -> 0 | H9: =SUM(H2:H8) -> 0 | I9: =SUM(I2:I8) -> 0 | ... W9: =SUM(W2:W8) -> 0
A10: Expense Item | B10: 1 | C10: 2 | D10: 3 | E10: 4 | F10: 5 | G10: 6 | H10: 7 | I10: 8 | J10: 9 | K10: 10 | L10: 11 | M10: 12 | N10: 13 | O10: 14 | P10: 15 | Q10: 16 | R10: 17 | S10: 18 | T10: 19 | U10: 20 | V10: Total
A11: ='Dashboard-Jan'!$C14 -> Reward-1 | V11: =('Dashboard-Jan'!D14)*(SUM(B11:U11)) -> 0
A12: ='Dashboard-Jan'!$C15 -> Reward-2 | V12: =('Dashboard-Jan'!D15)*(SUM(B12:U12)) -> 0
A13: ='Dashboard-Jan'!$C16 -> Reward-3 | V13: =('Dashboard-Jan'!D16)*(SUM(B13:U13)) -> 0
A14: TOTAL | B14: =SUM(B11:B13) -> 0 | C14: =SUM(C11:C13) -> 0 | D14: =SUM(D11:D13) -> 0 | E14: =SUM(E11:E13) -> 0 | F14: =SUM(F11:F13) -> 0 | G14: =SUM(G11:G13) -> 0 | H14: =SUM(H11:H13) -> 0 | I14: =SUM(I11:I13) -> 0 | ... V14: =SUM(V11:V13) -> 0

Sheet 17
A1: Task Name | B1: 1 | C1: 2 | D1: 3 | E1: 4 | F1: 5 | G1: 6 | H1: 7 | I1: 8 | J1: 9 | K1: 10 | L1: 11 | M1: 12 | N1: 13 | O1: 14 | P1: 15 | Q1: 16 | R1: 17 | S1: 18 | T1: 19 | U1: 20 | V1: Total | W1: Streak
A2: ='Dashboard-Jan'!$C2 -> Task-1 | V2: =(('Dashboard-Jan'!D2)*(SUM(B2:U2)))*((W2*'Dashboard-Jan'!$D$10)+1) -> 0 | W2: =IF('16'!V2 <> 0,('16'!W2)+1,0) -> 0
A3: ='Dashboard-Jan'!$C3 -> Task-2 | V3: =(('Dashboard-Jan'!D3)*(SUM(B3:U3)))*((W3*'Dashboard-Jan'!$D$10)+1) -> 0 | W3: =IF('16'!V3 <> 0,('16'!W3)+1,0) -> 0
A4: ='Dashboard-Jan'!$C4 -> Task-3 | V4: =(('Dashboard-Jan'!D4)*(SUM(B4:U4)))*((W4*'Dashboard-Jan'!$D$10)+1) -> 0 | W4: =IF('16'!V4 <> 0,('16'!W4)+1,0) -> 0
A5: ='Dashboard-Jan'!$C5 -> Task-4 | V5: =(('Dashboard-Jan'!D5)*(SUM(B5:U5)))*((W5*'Dashboard-Jan'!$D$10)+1) -> 0 | W5: =IF('16'!V5 <> 0,('16'!W5)+1,0) -> 0
A6: ='Dashboard-Jan'!$C6 -> Task-5 | V6: =(('Dashboard-Jan'!D6)*(SUM(B6:U6)))*((W6*'Dashboard-Jan'!$D$10)+1) -> 0 | W6: =IF('16'!V6 <> 0,('16'!W6)+1,0) -> 0
A7: ='Dashboard-Jan'!$C7 -> Task-6 | V7: =(('Dashboard-Jan'!D7)*(SUM(B7:U7)))*((W7*'Dashboard-Jan'!$D$10)+1) -> 0 | W7: =IF('16'!V7 <> 0,('16'!W7)+1,0) -> 0
A8: ='Dashboard-Jan'!$C8 -> Task-7 | V8: =(('Dashboard-Jan'!D8)*(SUM(B8:U8)))*((W8*'Dashboard-Jan'!$D$10)+1) -> 0 | W8: =IF('16'!V8 <> 0,('16'!W8)+1,0) -> 0
A9: TOTAL | B9: =SUM(B2:B8) -> 0 | C9: =SUM(C2:C8) -> 0 | D9: =SUM(D2:D8) -> 0 | E9: =SUM(E2:E8) -> 0 | F9: =SUM(F2:F8) -> 0 | G9: =SUM(G2:G8) -> 0 | H9: =SUM(H2:H8) -> 0 | I9: =SUM(I2:I8) -> 0 | ... W9: =SUM(W2:W8) -> 0
A10: Expense Item | B10: 1 | C10: 2 | D10: 3 | E10: 4 | F10: 5 | G10: 6 | H10: 7 | I10: 8 | J10: 9 | K10: 10 | L10: 11 | M10: 12 | N10: 13 | O10: 14 | P10: 15 | Q10: 16 | R10: 17 | S10: 18 | T10: 19 | U10: 20 | V10: Total
A11: ='Dashboard-Jan'!$C14 -> Reward-1 | V11: =('Dashboard-Jan'!D14)*(SUM(B11:U11)) -> 0
A12: ='Dashboard-Jan'!$C15 -> Reward-2 | V12: =('Dashboard-Jan'!D15)*(SUM(B12:U12)) -> 0
A13: ='Dashboard-Jan'!$C16 -> Reward-3 | V13: =('Dashboard-Jan'!D16)*(SUM(B13:U13)) -> 0
A14: TOTAL | B14: =SUM(B11:B13) -> 0 | C14: =SUM(C11:C13) -> 0 | D14: =SUM(D11:D13) -> 0 | E14: =SUM(E11:E13) -> 0 | F14: =SUM(F11:F13) -> 0 | G14: =SUM(G11:G13) -> 0 | H14: =SUM(H11:H13) -> 0 | I14: =SUM(I11:I13) -> 0 | ... V14: =SUM(V11:V13) -> 0

Sheet 18
A1: Task Name | B1: 1 | C1: 2 | D1: 3 | E1: 4 | F1: 5 | G1: 6 | H1: 7 | I1: 8 | J1: 9 | K1: 10 | L1: 11 | M1: 12 | N1: 13 | O1: 14 | P1: 15 | Q1: 16 | R1: 17 | S1: 18 | T1: 19 | U1: 20 | V1: Total | W1: Streak
A2: ='Dashboard-Jan'!$C2 -> Task-1 | V2: =(('Dashboard-Jan'!D2)*(SUM(B2:U2)))*((W2*'Dashboard-Jan'!$D$10)+1) -> 0 | W2: =IF('17'!V2 <> 0,('17'!W2)+1,0) -> 0
A3: ='Dashboard-Jan'!$C3 -> Task-2 | V3: =(('Dashboard-Jan'!D3)*(SUM(B3:U3)))*((W3*'Dashboard-Jan'!$D$10)+1) -> 0 | W3: =IF('17'!V3 <> 0,('17'!W3)+1,0) -> 0
A4: ='Dashboard-Jan'!$C4 -> Task-3 | V4: =(('Dashboard-Jan'!D4)*(SUM(B4:U4)))*((W4*'Dashboard-Jan'!$D$10)+1) -> 0 | W4: =IF('17'!V4 <> 0,('17'!W4)+1,0) -> 0
A5: ='Dashboard-Jan'!$C5 -> Task-4 | V5: =(('Dashboard-Jan'!D5)*(SUM(B5:U5)))*((W5*'Dashboard-Jan'!$D$10)+1) -> 0 | W5: =IF('17'!V5 <> 0,('17'!W5)+1,0) -> 0
A6: ='Dashboard-Jan'!$C6 -> Task-5 | V6: =(('Dashboard-Jan'!D6)*(SUM(B6:U6)))*((W6*'Dashboard-Jan'!$D$10)+1) -> 0 | W6: =IF('17'!V6 <> 0,('17'!W6)+1,0) -> 0
A7: ='Dashboard-Jan'!$C7 -> Task-6 | V7: =(('Dashboard-Jan'!D7)*(SUM(B7:U7)))*((W7*'Dashboard-Jan'!$D$10)+1) -> 0 | W7: =IF('17'!V7 <> 0,('17'!W7)+1,0) -> 0
A8: ='Dashboard-Jan'!$C8 -> Task-7 | V8: =(('Dashboard-Jan'!D8)*(SUM(B8:U8)))*((W8*'Dashboard-Jan'!$D$10)+1) -> 0 | W8: =IF('17'!V8 <> 0,('17'!W8)+1,0) -> 0
A9: TOTAL | B9: =SUM(B2:B8) -> 0 | C9: =SUM(C2:C8) -> 0 | D9: =SUM(D2:D8) -> 0 | E9: =SUM(E2:E8) -> 0 | F9: =SUM(F2:F8) -> 0 | G9: =SUM(G2:G8) -> 0 | H9: =SUM(H2:H8) -> 0 | I9: =SUM(I2:I8) -> 0 | ... W9: =SUM(W2:W8) -> 0
A10: Expense Item | B10: 1 | C10: 2 | D10: 3 | E10: 4 | F10: 5 | G10: 6 | H10: 7 | I10: 8 | J10: 9 | K10: 10 | L10: 11 | M10: 12 | N10: 13 | O10: 14 | P10: 15 | Q10: 16 | R10: 17 | S10: 18 | T10: 19 | U10: 20 | V10: Total
A11: ='Dashboard-Jan'!$C14 -> Reward-1 | V11: =('Dashboard-Jan'!D14)*(SUM(B11:U11)) -> 0
A12: ='Dashboard-Jan'!$C15 -> Reward-2 | V12: =('Dashboard-Jan'!D15)*(SUM(B12:U12)) -> 0
A13: ='Dashboard-Jan'!$C16 -> Reward-3 | V13: =('Dashboard-Jan'!D16)*(SUM(B13:U13)) -> 0
A14: TOTAL | B14: =SUM(B11:B13) -> 0 | C14: =SUM(C11:C13) -> 0 | D14: =SUM(D11:D13) -> 0 | E14: =SUM(E11:E13) -> 0 | F14: =SUM(F11:F13) -> 0 | G14: =SUM(G11:G13) -> 0 | H14: =SUM(H11:H13) -> 0 | I14: =SUM(I11:I13) -> 0 | ... V14: =SUM(V11:V13) -> 0

Sheet 19
A1: Task Name | B1: 1 | C1: 2 | D1: 3 | E1: 4 | F1: 5 | G1: 6 | H1: 7 | I1: 8 | J1: 9 | K1: 10 | L1: 11 | M1: 12 | N1: 13 | O1: 14 | P1: 15 | Q1: 16 | R1: 17 | S1: 18 | T1: 19 | U1: 20 | V1: Total | W1: Streak
A2: ='Dashboard-Jan'!$C2 -> Task-1 | V2: =(('Dashboard-Jan'!D2)*(SUM(B2:U2)))*((W2*'Dashboard-Jan'!$D$10)+1) -> 0 | W2: =IF('18'!V2 <> 0,('18'!W2)+1,0) -> 0
A3: ='Dashboard-Jan'!$C3 -> Task-2 | V3: =(('Dashboard-Jan'!D3)*(SUM(B3:U3)))*((W3*'Dashboard-Jan'!$D$10)+1) -> 0 | W3: =IF('18'!V3 <> 0,('18'!W3)+1,0) -> 0
A4: ='Dashboard-Jan'!$C4 -> Task-3 | V4: =(('Dashboard-Jan'!D4)*(SUM(B4:U4)))*((W4*'Dashboard-Jan'!$D$10)+1) -> 0 | W4: =IF('18'!V4 <> 0,('18'!W4)+1,0) -> 0
A5: ='Dashboard-Jan'!$C5 -> Task-4 | V5: =(('Dashboard-Jan'!D5)*(SUM(B5:U5)))*((W5*'Dashboard-Jan'!$D$10)+1) -> 0 | W5: =IF('18'!V5 <> 0,('18'!W5)+1,0) -> 0
A6: ='Dashboard-Jan'!$C6 -> Task-5 | V6: =(('Dashboard-Jan'!D6)*(SUM(B6:U6)))*((W6*'Dashboard-Jan'!$D$10)+1) -> 0 | W6: =IF('18'!V6 <> 0,('18'!W6)+1,0) -> 0
A7: ='Dashboard-Jan'!$C7 -> Task-6 | V7: =(('Dashboard-Jan'!D7)*(SUM(B7:U7)))*((W7*'Dashboard-Jan'!$D$10)+1) -> 0 | W7: =IF('18'!V7 <> 0,('18'!W7)+1,0) -> 0
A8: ='Dashboard-Jan'!$C8 -> Task-7 | V8: =(('Dashboard-Jan'!D8)*(SUM(B8:U8)))*((W8*'Dashboard-Jan'!$D$10)+1) -> 0 | W8: =IF('18'!V8 <> 0,('18'!W8)+1,0) -> 0
A9: TOTAL | B9: =SUM(B2:B8) -> 0 | C9: =SUM(C2:C8) -> 0 | D9: =SUM(D2:D8) -> 0 | E9: =SUM(E2:E8) -> 0 | F9: =SUM(F2:F8) -> 0 | G9: =SUM(G2:G8) -> 0 | H9: =SUM(H2:H8) -> 0 | I9: =SUM(I2:I8) -> 0 | ... W9: =SUM(W2:W8) -> 0
A10: Expense Item | B10: 1 | C10: 2 | D10: 3 | E10: 4 | F10: 5 | G10: 6 | H10: 7 | I10: 8 | J10: 9 | K10: 10 | L10: 11 | M10: 12 | N10: 13 | O10: 14 | P10: 15 | Q10: 16 | R10: 17 | S10: 18 | T10: 19 | U10: 20 | V10: Total
A11: ='Dashboard-Jan'!$C14 -> Reward-1 | V11: =('Dashboard-Jan'!D14)*(SUM(B11:U11)) -> 0
A12: ='Dashboard-Jan'!$C15 -> Reward-2 | V12: =('Dashboard-Jan'!D15)*(SUM(B12:U12)) -> 0
A13: ='Dashboard-Jan'!$C16 -> Reward-3 | V13: =('Dashboard-Jan'!D16)*(SUM(B13:U13)) -> 0
A14: TOTAL | B14: =SUM(B11:B13) -> 0 | C14: =SUM(C11:C13) -> 0 | D14: =SUM(D11:D13) -> 0 | E14: =SUM(E11:E13) -> 0 | F14: =SUM(F11:F13) -> 0 | G14: =SUM(G11:G13) -> 0 | H14: =SUM(H11:H13) -> 0 | I14: =SUM(I11:I13) -> 0 | ... V14: =SUM(V11:V13) -> 0

Sheet 20
A1: Task Name | B1: 1 | C1: 2 | D1: 3 | E1: 4 | F1: 5 | G1: 6 | H1: 7 | I1: 8 | J1: 9 | K1: 10 | L1: 11 | M1: 12 | N1: 13 | O1: 14 | P1: 15 | Q1: 16 | R1: 17 | S1: 18 | T1: 19 | U1: 20 | V1: Total | W1: Streak
A2: ='Dashboard-Jan'!$C2 -> Task-1 | V2: =(('Dashboard-Jan'!D2)*(SUM(B2:U2)))*((W2*'Dashboard-Jan'!$D$10)+1) -> 0 | W2: =IF('19'!V2 <> 0,('19'!W2)+1,0) -> 0
A3: ='Dashboard-Jan'!$C3 -> Task-2 | V3: =(('Dashboard-Jan'!D3)*(SUM(B3:U3)))*((W3*'Dashboard-Jan'!$D$10)+1) -> 0 | W3: =IF('19'!V3 <> 0,('19'!W3)+1,0) -> 0
A4: ='Dashboard-Jan'!$C4 -> Task-3 | V4: =(('Dashboard-Jan'!D4)*(SUM(B4:U4)))*((W4*'Dashboard-Jan'!$D$10)+1) -> 0 | W4: =IF('19'!V4 <> 0,('19'!W4)+1,0) -> 0
A5: ='Dashboard-Jan'!$C5 -> Task-4 | V5: =(('Dashboard-Jan'!D5)*(SUM(B5:U5)))*((W5*'Dashboard-Jan'!$D$10)+1) -> 0 | W5: =IF('19'!V5 <> 0,('19'!W5)+1,0) -> 0
A6: ='Dashboard-Jan'!$C6 -> Task-5 | V6: =(('Dashboard-Jan'!D6)*(SUM(B6:U6)))*((W6*'Dashboard-Jan'!$D$10)+1) -> 0 | W6: =IF('19'!V6 <> 0,('19'!W6)+1,0) -> 0
A7: ='Dashboard-Jan'!$C7 -> Task-6 | V7: =(('Dashboard-Jan'!D7)*(SUM(B7:U7)))*((W7*'Dashboard-Jan'!$D$10)+1) -> 0 | W7: =IF('19'!V7 <> 0,('19'!W7)+1,0) -> 0
A8: ='Dashboard-Jan'!$C8 -> Task-7 | V8: =(('Dashboard-Jan'!D8)*(SUM(B8:U8)))*((W8*'Dashboard-Jan'!$D$10)+1) -> 0 | W8: =IF('19'!V8 <> 0,('19'!W8)+1,0) -> 0
A9: TOTAL | B9: =SUM(B2:B8) -> 0 | C9: =SUM(C2:C8) -> 0 | D9: =SUM(D2:D8) -> 0 | E9: =SUM(E2:E8) -> 0 | F9: =SUM(F2:F8) -> 0 | G9: =SUM(G2:G8) -> 0 | H9: =SUM(H2:H8) -> 0 | I9: =SUM(I2:I8) -> 0 | ... W9: =SUM(W2:W8) -> 0
A10: Expense Item | B10: 1 | C10: 2 | D10: 3 | E10: 4 | F10: 5 | G10: 6 | H10: 7 | I10: 8 | J10: 9 | K10: 10 | L10: 11 | M10: 12 | N10: 13 | O10: 14 | P10: 15 | Q10: 16 | R10: 17 | S10: 18 | T10: 19 | U10: 20 | V10: Total
A11: ='Dashboard-Jan'!$C14 -> Reward-1 | V11: =('Dashboard-Jan'!D14)*(SUM(B11:U11)) -> 0
A12: ='Dashboard-Jan'!$C15 -> Reward-2 | V12: =('Dashboard-Jan'!D15)*(SUM(B12:U12)) -> 0
A13: ='Dashboard-Jan'!$C16 -> Reward-3 | V13: =('Dashboard-Jan'!D16)*(SUM(B13:U13)) -> 0
A14: TOTAL | B14: =SUM(B11:B13) -> 0 | C14: =SUM(C11:C13) -> 0 | D14: =SUM(D11:D13) -> 0 | E14: =SUM(E11:E13) -> 0 | F14: =SUM(F11:F13) -> 0 | G14: =SUM(G11:G13) -> 0 | H14: =SUM(H11:H13) -> 0 | I14: =SUM(I11:I13) -> 0 | ... V14: =SUM(V11:V13) -> 0

Sheet 21
A1: Task Name | B1: 1 | C1: 2 | D1: 3 | E1: 4 | F1: 5 | G1: 6 | H1: 7 | I1: 8 | J1: 9 | K1: 10 | L1: 11 | M1: 12 | N1: 13 | O1: 14 | P1: 15 | Q1: 16 | R1: 17 | S1: 18 | T1: 19 | U1: 20 | V1: Total | W1: Streak
A2: ='Dashboard-Jan'!$C2 -> Task-1 | V2: =(('Dashboard-Jan'!D2)*(SUM(B2:U2)))*((W2*'Dashboard-Jan'!$D$10)+1) -> 0 | W2: =IF('20'!V2 <> 0,('20'!W2)+1,0) -> 0
A3: ='Dashboard-Jan'!$C3 -> Task-2 | V3: =(('Dashboard-Jan'!D3)*(SUM(B3:U3)))*((W3*'Dashboard-Jan'!$D$10)+1) -> 0 | W3: =IF('20'!V3 <> 0,('20'!W3)+1,0) -> 0
A4: ='Dashboard-Jan'!$C4 -> Task-3 | V4: =(('Dashboard-Jan'!D4)*(SUM(B4:U4)))*((W4*'Dashboard-Jan'!$D$10)+1) -> 0 | W4: =IF('20'!V4 <> 0,('20'!W4)+1,0) -> 0
A5: ='Dashboard-Jan'!$C5 -> Task-4 | V5: =(('Dashboard-Jan'!D5)*(SUM(B5:U5)))*((W5*'Dashboard-Jan'!$D$10)+1) -> 0 | W5: =IF('20'!V5 <> 0,('20'!W5)+1,0) -> 0
A6: ='Dashboard-Jan'!$C6 -> Task-5 | V6: =(('Dashboard-Jan'!D6)*(SUM(B6:U6)))*((W6*'Dashboard-Jan'!$D$10)+1) -> 0 | W6: =IF('20'!V6 <> 0,('20'!W6)+1,0) -> 0
A7: ='Dashboard-Jan'!$C7 -> Task-6 | V7: =(('Dashboard-Jan'!D7)*(SUM(B7:U7)))*((W7*'Dashboard-Jan'!$D$10)+1) -> 0 | W7: =IF('20'!V7 <> 0,('20'!W7)+1,0) -> 0
A8: ='Dashboard-Jan'!$C8 -> Task-7 | V8: =(('Dashboard-Jan'!D8)*(SUM(B8:U8)))*((W8*'Dashboard-Jan'!$D$10)+1) -> 0 | W8: =IF('20'!V8 <> 0,('20'!W8)+1,0) -> 0
A9: TOTAL | B9: =SUM(B2:B8) -> 0 | C9: =SUM(C2:C8) -> 0 | D9: =SUM(D2:D8) -> 0 | E9: =SUM(E2:E8) -> 0 | F9: =SUM(F2:F8) -> 0 | G9: =SUM(G2:G8) -> 0 | H9: =SUM(H2:H8) -> 0 | I9: =SUM(I2:I8) -> 0 | ... W9: =SUM(W2:W8) -> 0
A10: Expense Item | B10: 1 | C10: 2 | D10: 3 | E10: 4 | F10: 5 | G10: 6 | H10: 7 | I10: 8 | J10: 9 | K10: 10 | L10: 11 | M10: 12 | N10: 13 | O10: 14 | P10: 15 | Q10: 16 | R10: 17 | S10: 18 | T10: 19 | U10: 20 | V10: Total
A11: ='Dashboard-Jan'!$C14 -> Reward-1 | V11: =('Dashboard-Jan'!D14)*(SUM(B11:U11)) -> 0
A12: ='Dashboard-Jan'!$C15 -> Reward-2 | V12: =('Dashboard-Jan'!D15)*(SUM(B12:U12)) -> 0
A13: ='Dashboard-Jan'!$C16 -> Reward-3 | V13: =('Dashboard-Jan'!D16)*(SUM(B13:U13)) -> 0
A14: TOTAL | B14: =SUM(B11:B13) -> 0 | C14: =SUM(C11:C13) -> 0 | D14: =SUM(D11:D13) -> 0 | E14: =SUM(E11:E13) -> 0 | F14: =SUM(F11:F13) -> 0 | G14: =SUM(G11:G13) -> 0 | H14: =SUM(H11:H13) -> 0 | I14: =SUM(I11:I13) -> 0 | ... V14: =SUM(V11:V13) -> 0

Sheet 22
